Workbook

Sheet Даты занятий
A1: 251 | B1: БИВ | C1: 45917 | D1: 45924 | E1: 45931 | F1: 45938 | H1: Ерохина | L1: 45910 | M1: 45910 | N1: 45912 | O1: 45919 | P1: 45924 | Q1: 45926 | R1: 45931 | S1: 45938 | T1: 45940 | U1: 45945 | V1: Ерохина | X1: =CHOOSE(MATCH(X$10,$L$22:$U$22),$L23,$M23,$N23,$O23,$P23,$Q23,$R23,$S23) -> 45932 | Y1: =CHOOSE(MATCH(Y$10,$L$22:$U$22),$L23,$M23,$N23,$O23,$P23,$Q23,$R23,$S23) -> 45946 | Z1: =IF(OR(CHOOSE(MATCH(Z$10,$L$22:$U$22)+1,$L23,$M23,$N23,$O23,$P23,$Q23,$R23,$S23)>($J$14),CHOOSE(MATCH(Z$10,$L$22:$U$22)+1,$L23,$M23,$N23,$O23,$P23,$Q23,$R23,$S23)=0),"-----",CHOOSE(MATCH(Z$10,$L$22:$U$22)+1,$L23,$M23,$N23,$O23,$P23,$Q23,$R23,$S23)) -> 45939 | AA1: ----- | AB1: =IF(OR(CHOOSE(MATCH(AB$10,$L$22:$U$22)+2,$L23,$M23,$N23,$O23,$P23,$Q23,$R23,$S23)>($J$14),CHOOSE(MATCH(AB$10,$L$22:$U$22)+2,$L23,$M23,$N23,$O23,$P23,$Q23,$R23,$S23)=0),"-----",CHOOSE(MATCH(AB$10,$L$22:$U$22)+2,$L23,$M23,$N23,$O23,$P23,$Q23,$R23,$S23)) -> 45946 | AC1: ----- | AE1: =CHOOSE(MATCH(AE$10,$L$32:$U$32),$L33,$M33,$N33,$O33,$P33,$Q33,$R33,$S33) -> 45932 | AF1: =CHOOSE(MATCH(AF$10,$L$32:$U$32),$L33,$M33,$N33,$O33,$P33,$Q33,$R33,$S33) -> 45946 | AG1: =IF(OR(CHOOSE(MATCH(AG$10,$L$32:$U$32)+1,$L33,$M33,$N33,$O33,$P33,$Q33,$R33,$S33)>($J$14),CHOOSE(MATCH(AG$10,$L$32:$U$32)+1,$L33,$M33,$N33,$O33,$P33,$Q33,$R33,$S33)=0),"-----",CHOOSE(MATCH(AG$10,$L$32:$U$32)+1,$L33,$M33,$N33,$O33,$P33,$Q33,$R33,$S33)) -> 45939 | AH1: ----- | AI1: =IF(OR(CHOOSE(MATCH(AI$10,$L$32:$U$32)+2,$L33,$M33,$N33,$O33,$P33,$Q33,$R33,$S33)>($J$14),CHOOSE(MATCH(AI$10,$L$32:$U$32)+2,$L33,$M33,$N33,$O33,$P33,$Q33,$R33,$S33)=0),"-----",CHOOSE(MATCH(AI$10,$L$32:$U$32)+2,$L33,$M33,$N33,$O33,$P33,$Q33,$R33,$S33)) -> 45946 | AJ1: -----
A2: 252 | B2: БИВ | C2: 45910 | D2: 45917 | E2: 45924 | F2: 45931 | H2: Ерохина | L2: 45910 | M2: 45910 | N2: 45912 | O2: 45919 | P2: 45924 | Q2: 45926 | R2: 45931 | S2: 45938 | T2: 45940 | U2: 45945 | V2: Ерохина | X2: =CHOOSE(MATCH(X$10,$L$22:$U$22),$L24,$M24,$N24,$O24,$P24,$Q24,$R24,$S24) -> 45926 | Y2: =CHOOSE(MATCH(Y$10,$L$22:$U$22),$L24,$M24,$N24,$O24,$P24,$Q24,$R24,$S24) -> 45940 | Z2: =IF(OR(CHOOSE(MATCH(Z$10,$L$22:$U$22)+1,$L24,$M24,$N24,$O24,$P24,$Q24,$R24,$S24)>($J$14),CHOOSE(MATCH(Z$10,$L$22:$U$22)+1,$L24,$M24,$N24,$O24,$P24,$Q24,$R24,$S24)=0),"-----",CHOOSE(MATCH(Z$10,$L$22:$U$22)+1,$L24,$M24,$N24,$O24,$P24,$Q24,$R24,$S24)) -> 45933 | AA2: ----- | AB2: =IF(OR(CHOOSE(MATCH(AB$10,$L$22:$U$22)+2,$L24,$M24,$N24,$O24,$P24,$Q24,$R24,$S24)>($J$14),CHOOSE(MATCH(AB$10,$L$22:$U$22)+2,$L24,$M24,$N24,$O24,$P24,$Q24,$R24,$S24)=0),"-----",CHOOSE(MATCH(AB$10,$L$22:$U$22)+2,$L24,$M24,$N24,$O24,$P24,$Q24,$R24,$S24)) -> 45940 | AC2: ----- | AE2: =CHOOSE(MATCH(AE$10,$L$32:$U$32),$L34,$M34,$N34,$O34,$P34,$Q34,$R34,$S34) -> 45926 | AF2: =CHOOSE(MATCH(AF$10,$L$32:$U$32),$L34,$M34,$N34,$O34,$P34,$Q34,$R34,$S34) -> 45940 | AG2: =IF(OR(CHOOSE(MATCH(AG$10,$L$32:$U$32)+1,$L34,$M34,$N34,$O34,$P34,$Q34,$R34,$S34)>($J$14),CHOOSE(MATCH(AG$10,$L$32:$U$32)+1,$L34,$M34,$N34,$O34,$P34,$Q34,$R34,$S34)=0),"-----",CHOOSE(MATCH(AG$10,$L$32:$U$32)+1,$L34,$M34,$N34,$O34,$P34,$Q34,$R34,$S34)) -> 45933 | AH2: ----- | AI2: =IF(OR(CHOOSE(MATCH(AI$10,$L$32:$U$32)+2,$L34,$M34,$N34,$O34,$P34,$Q34,$R34,$S34)>($J$14),CHOOSE(MATCH(AI$10,$L$32:$U$32)+2,$L34,$M34,$N34,$O34,$P34,$Q34,$R34,$S34)=0),"-----",CHOOSE(MATCH(AI$10,$L$32:$U$32)+2,$L34,$M34,$N34,$O34,$P34,$Q34,$R34,$S34)) -> 45940 | AJ2: -----
A3: 253 | B3: БИВ | C3: 45910 | D3: 45917 | E3: 45924 | F3: 45931 | H3: Ерохина | L3: 45910 | M3: 45910 | N3: 45912 | O3: 45919 | P3: 45924 | Q3: 45926 | R3: 45931 | S3: 45938 | T3: 45940 | U3: 45945 | V3: Ерохина | X3: =CHOOSE(MATCH(X$10,$L$22:$U$22),$L25,$M25,$N25,$O25,$P25,$Q25,$R25,$S25) -> 45931 | Y3: =CHOOSE(MATCH(Y$10,$L$22:$U$22),$L25,$M25,$N25,$O25,$P25,$Q25,$R25,$S25) -> 45945 | Z3: =IF(OR(CHOOSE(MATCH(Z$10,$L$22:$U$22)+1,$L25,$M25,$N25,$O25,$P25,$Q25,$R25,$S25)>($J$14),CHOOSE(MATCH(Z$10,$L$22:$U$22)+1,$L25,$M25,$N25,$O25,$P25,$Q25,$R25,$S25)=0),"-----",CHOOSE(MATCH(Z$10,$L$22:$U$22)+1,$L25,$M25,$N25,$O25,$P25,$Q25,$R25,$S25)) -> 45938 | AA3: ----- | AB3: =IF(OR(CHOOSE(MATCH(AB$10,$L$22:$U$22)+2,$L25,$M25,$N25,$O25,$P25,$Q25,$R25,$S25)>($J$14),CHOOSE(MATCH(AB$10,$L$22:$U$22)+2,$L25,$M25,$N25,$O25,$P25,$Q25,$R25,$S25)=0),"-----",CHOOSE(MATCH(AB$10,$L$22:$U$22)+2,$L25,$M25,$N25,$O25,$P25,$Q25,$R25,$S25)) -> 45945 | AC3: ----- | AE3: =CHOOSE(MATCH(AE$10,$L$32:$U$32),$L35,$M35,$N35,$O35,$P35,$Q35,$R35,$S35) -> 45931 | AF3: =CHOOSE(MATCH(AF$10,$L$32:$U$32),$L35,$M35,$N35,$O35,$P35,$Q35,$R35,$S35) -> 45945 | AG3: =IF(OR(CHOOSE(MATCH(AG$10,$L$32:$U$32)+1,$L35,$M35,$N35,$O35,$P35,$Q35,$R35,$S35)>($J$14),CHOOSE(MATCH(AG$10,$L$32:$U$32)+1,$L35,$M35,$N35,$O35,$P35,$Q35,$R35,$S35)=0),"-----",CHOOSE(MATCH(AG$10,$L$32:$U$32)+1,$L35,$M35,$N35,$O35,$P35,$Q35,$R35,$S35)) -> 45938 | AH3: ----- | AI3: =IF(OR(CHOOSE(MATCH(AI$10,$L$32:$U$32)+2,$L35,$M35,$N35,$O35,$P35,$Q35,$R35,$S35)>($J$14),CHOOSE(MATCH(AI$10,$L$32:$U$32)+2,$L35,$M35,$N35,$O35,$P35,$Q35,$R35,$S35)=0),"-----",CHOOSE(MATCH(AI$10,$L$32:$U$32)+2,$L35,$M35,$N35,$O35,$P35,$Q35,$R35,$S35)) -> 45945 | AJ3: -----
A4: 254 | B4: БИВ | C4: 45911 | D4: 45918 | E4: 45925 | F4: 45932 | H4: Ерохина | L4: 45910 | M4: 45910 | N4: 45912 | O4: 45919 | P4: 45924 | Q4: 45926 | R4: 45931 | S4: 45938 | T4: 45940 | U4: 45945 | V4: Ерохина | X4: =CHOOSE(MATCH(X$10,$L$22:$U$22),$L26,$M26,$N26,$O26,$P26,$Q26,$R26,$S26) -> 45931 | Y4: =CHOOSE(MATCH(Y$10,$L$22:$U$22),$L26,$M26,$N26,$O26,$P26,$Q26,$R26,$S26) -> 45945 | Z4: =IF(OR(CHOOSE(MATCH(Z$10,$L$22:$U$22)+1,$L26,$M26,$N26,$O26,$P26,$Q26,$R26,$S26)>($J$14),CHOOSE(MATCH(Z$10,$L$22:$U$22)+1,$L26,$M26,$N26,$O26,$P26,$Q26,$R26,$S26)=0),"-----",CHOOSE(MATCH(Z$10,$L$22:$U$22)+1,$L26,$M26,$N26,$O26,$P26,$Q26,$R26,$S26)) -> 45938 | AA4: ----- | AB4: =IF(OR(CHOOSE(MATCH(AB$10,$L$22:$U$22)+2,$L26,$M26,$N26,$O26,$P26,$Q26,$R26,$S26)>($J$14),CHOOSE(MATCH(AB$10,$L$22:$U$22)+2,$L26,$M26,$N26,$O26,$P26,$Q26,$R26,$S26)=0),"-----",CHOOSE(MATCH(AB$10,$L$22:$U$22)+2,$L26,$M26,$N26,$O26,$P26,$Q26,$R26,$S26)) -> 45945 | AC4: ----- | AE4: =CHOOSE(MATCH(AE$10,$L$32:$U$32),$L36,$M36,$N36,$O36,$P36,$Q36,$R36,$S36) -> 45932 | AF4: =CHOOSE(MATCH(AF$10,$L$32:$U$32),$L36,$M36,$N36,$O36,$P36,$Q36,$R36,$S36) -> 45946 | AG4: =IF(OR(CHOOSE(MATCH(AG$10,$L$32:$U$32)+1,$L36,$M36,$N36,$O36,$P36,$Q36,$R36,$S36)>($J$14),CHOOSE(MATCH(AG$10,$L$32:$U$32)+1,$L36,$M36,$N36,$O36,$P36,$Q36,$R36,$S36)=0),"-----",CHOOSE(MATCH(AG$10,$L$32:$U$32)+1,$L36,$M36,$N36,$O36,$P36,$Q36,$R36,$S36)) -> 45939 | AH4: ----- | AI4: =IF(OR(CHOOSE(MATCH(AI$10,$L$32:$U$32)+2,$L36,$M36,$N36,$O36,$P36,$Q36,$R36,$S36)>($J$14),CHOOSE(MATCH(AI$10,$L$32:$U$32)+2,$L36,$M36,$N36,$O36,$P36,$Q36,$R36,$S36)=0),"-----",CHOOSE(MATCH(AI$10,$L$32:$U$32)+2,$L36,$M36,$N36,$O36,$P36,$Q36,$R36,$S36)) -> 45946 | AJ4: -----
A5: 255 | B5: БИВ | C5: 45911 | D5: 45918 | E5: 45925 | F5: 45932 | H5: Ерохина | L5: 45911 | M5: 45918 | N5: 45925 | O5: 45932 | P5: 45933 | Q5: 45933 | R5: 45938 | S5: 45939 | T5: 45940 | U5: 45945 | V5: Ерохина | X5: =CHOOSE(MATCH(X$10,$L$22:$U$22),$L27,$M27,$N27,$O27,$P27,$Q27,$R27,$S27) -> 45933 | Y5: =CHOOSE(MATCH(Y$10,$L$22:$U$22),$L27,$M27,$N27,$O27,$P27,$Q27,$R27,$S27) -> 45945 | Z5: =IF(OR(CHOOSE(MATCH(Z$10,$L$22:$U$22)+1,$L27,$M27,$N27,$O27,$P27,$Q27,$R27,$S27)>($J$14),CHOOSE(MATCH(Z$10,$L$22:$U$22)+1,$L27,$M27,$N27,$O27,$P27,$Q27,$R27,$S27)=0),"-----",CHOOSE(MATCH(Z$10,$L$22:$U$22)+1,$L27,$M27,$N27,$O27,$P27,$Q27,$R27,$S27)) -> 45940 | AA5: ----- | AB5: =IF(OR(CHOOSE(MATCH(AB$10,$L$22:$U$22)+2,$L27,$M27,$N27,$O27,$P27,$Q27,$R27,$S27)>($J$14),CHOOSE(MATCH(AB$10,$L$22:$U$22)+2,$L27,$M27,$N27,$O27,$P27,$Q27,$R27,$S27)=0),"-----",CHOOSE(MATCH(AB$10,$L$22:$U$22)+2,$L27,$M27,$N27,$O27,$P27,$Q27,$R27,$S27)) -> 45945 | AC5: ----- | AE5: =CHOOSE(MATCH(AE$10,$L$32:$U$32),$L37,$M37,$N37,$O37,$P37,$Q37,$R37,$S37) -> 45932 | AF5: =CHOOSE(MATCH(AF$10,$L$32:$U$32),$L37,$M37,$N37,$O37,$P37,$Q37,$R37,$S37) -> 45946 | AG5: =IF(OR(CHOOSE(MATCH(AG$10,$L$32:$U$32)+1,$L37,$M37,$N37,$O37,$P37,$Q37,$R37,$S37)>($J$14),CHOOSE(MATCH(AG$10,$L$32:$U$32)+1,$L37,$M37,$N37,$O37,$P37,$Q37,$R37,$S37)=0),"-----",CHOOSE(MATCH(AG$10,$L$32:$U$32)+1,$L37,$M37,$N37,$O37,$P37,$Q37,$R37,$S37)) -> 45939 | AH5: ----- | AI5: =IF(OR(CHOOSE(MATCH(AI$10,$L$32:$U$32)+2,$L37,$M37,$N37,$O37,$P37,$Q37,$R37,$S37)>($J$14),CHOOSE(MATCH(AI$10,$L$32:$U$32)+2,$L37,$M37,$N37,$O37,$P37,$Q37,$R37,$S37)=0),"-----",CHOOSE(MATCH(AI$10,$L$32:$U$32)+2,$L37,$M37,$N37,$O37,$P37,$Q37,$R37,$S37)) -> 45946 | AJ5: -----
A6: 256 | B6: БИВ | C6: 45911 | D6: 45918 | E6: 45925 | F6: 45932 | H6: Ерохина | L6: 45911 | M6: 45918 | N6: 45925 | O6: 45932 | P6: 45933 | Q6: 45933 | R6: 45938 | S6: 45939 | T6: 45940 | U6: 45945 | V6: Ерохина | X6: =CHOOSE(MATCH(X$10,$L$22:$U$22),$L28,$M28,$N28,$O28,$P28,$Q28,$R28,$S28) -> 45932 | Y6: =CHOOSE(MATCH(Y$10,$L$22:$U$22),$L28,$M28,$N28,$O28,$P28,$Q28,$R28,$S28) -> 45946 | Z6: =IF(OR(CHOOSE(MATCH(Z$10,$L$22:$U$22)+1,$L28,$M28,$N28,$O28,$P28,$Q28,$R28,$S28)>($J$14),CHOOSE(MATCH(Z$10,$L$22:$U$22)+1,$L28,$M28,$N28,$O28,$P28,$Q28,$R28,$S28)=0),"-----",CHOOSE(MATCH(Z$10,$L$22:$U$22)+1,$L28,$M28,$N28,$O28,$P28,$Q28,$R28,$S28)) -> 45939 | AA6: ----- | AB6: =IF(OR(CHOOSE(MATCH(AB$10,$L$22:$U$22)+2,$L28,$M28,$N28,$O28,$P28,$Q28,$R28,$S28)>($J$14),CHOOSE(MATCH(AB$10,$L$22:$U$22)+2,$L28,$M28,$N28,$O28,$P28,$Q28,$R28,$S28)=0),"-----",CHOOSE(MATCH(AB$10,$L$22:$U$22)+2,$L28,$M28,$N28,$O28,$P28,$Q28,$R28,$S28)) -> 45946 | AC6: ----- | AE6: =CHOOSE(MATCH(AE$10,$L$32:$U$32),$L38,$M38,$N38,$O38,$P38,$Q38,$R38,$S38) -> 45929 | AF6: =CHOOSE(MATCH(AF$10,$L$32:$U$32),$L38,$M38,$N38,$O38,$P38,$Q38,$R38,$S38) -> 45943 | AG6: =IF(OR(CHOOSE(MATCH(AG$10,$L$32:$U$32)+1,$L38,$M38,$N38,$O38,$P38,$Q38,$R38,$S38)>($J$14),CHOOSE(MATCH(AG$10,$L$32:$U$32)+1,$L38,$M38,$N38,$O38,$P38,$Q38,$R38,$S38)=0),"-----",CHOOSE(MATCH(AG$10,$L$32:$U$32)+1,$L38,$M38,$N38,$O38,$P38,$Q38,$R38,$S38)) -> 45936 | AH6: ----- | AI6: =IF(OR(CHOOSE(MATCH(AI$10,$L$32:$U$32)+2,$L38,$M38,$N38,$O38,$P38,$Q38,$R38,$S38)>($J$14),CHOOSE(MATCH(AI$10,$L$32:$U$32)+2,$L38,$M38,$N38,$O38,$P38,$Q38,$R38,$S38)=0),"-----",CHOOSE(MATCH(AI$10,$L$32:$U$32)+2,$L38,$M38,$N38,$O38,$P38,$Q38,$R38,$S38)) -> 45943 | AJ6: -----
A7: 257 | B7: БИВ | C7: 45912 | D7: 45912 | E7: 45919 | F7: 45919 | H7: Ерохина | L7: 45911 | M7: 45918 | N7: 45925 | O7: 45932 | P7: 45933 | Q7: 45933 | R7: 45938 | S7: 45939 | T7: 45940 | U7: 45945 | V7: Ерохина | X7: =CHOOSE(MATCH(X$10,$L$22:$U$22),$L29,$M29,$N29,$O29,$P29,$Q29,$R29,$S29) -> 45931 | Y7: =CHOOSE(MATCH(Y$10,$L$22:$U$22),$L29,$M29,$N29,$O29,$P29,$Q29,$R29,$S29) -> 45952 | Z7: =IF(OR(CHOOSE(MATCH(Z$10,$L$22:$U$22)+1,$L29,$M29,$N29,$O29,$P29,$Q29,$R29,$S29)>($J$14),CHOOSE(MATCH(Z$10,$L$22:$U$22)+1,$L29,$M29,$N29,$O29,$P29,$Q29,$R29,$S29)=0),"-----",CHOOSE(MATCH(Z$10,$L$22:$U$22)+1,$L29,$M29,$N29,$O29,$P29,$Q29,$R29,$S29)) -> 45938 | AA7: ----- | AB7: =IF(OR(CHOOSE(MATCH(AB$10,$L$22:$U$22)+2,$L29,$M29,$N29,$O29,$P29,$Q29,$R29,$S29)>($J$14),CHOOSE(MATCH(AB$10,$L$22:$U$22)+2,$L29,$M29,$N29,$O29,$P29,$Q29,$R29,$S29)=0),"-----",CHOOSE(MATCH(AB$10,$L$22:$U$22)+2,$L29,$M29,$N29,$O29,$P29,$Q29,$R29,$S29)) -> 45952 | AC7: ----- | AE7: =CHOOSE(MATCH(AE$10,$L$32:$U$32),$L39,$M39,$N39,$O39,$P39,$Q39,$R39,$S39) -> 45929 | AF7: =CHOOSE(MATCH(AF$10,$L$32:$U$32),$L39,$M39,$N39,$O39,$P39,$Q39,$R39,$S39) -> 45943 | AG7: =IF(OR(CHOOSE(MATCH(AG$10,$L$32:$U$32)+1,$L39,$M39,$N39,$O39,$P39,$Q39,$R39,$S39)>($J$14),CHOOSE(MATCH(AG$10,$L$32:$U$32)+1,$L39,$M39,$N39,$O39,$P39,$Q39,$R39,$S39)=0),"-----",CHOOSE(MATCH(AG$10,$L$32:$U$32)+1,$L39,$M39,$N39,$O39,$P39,$Q39,$R39,$S39)) -> 45936 | AH7: ----- | AI7: =IF(OR(CHOOSE(MATCH(AI$10,$L$32:$U$32)+2,$L39,$M39,$N39,$O39,$P39,$Q39,$R39,$S39)>($J$14),CHOOSE(MATCH(AI$10,$L$32:$U$32)+2,$L39,$M39,$N39,$O39,$P39,$Q39,$R39,$S39)=0),"-----",CHOOSE(MATCH(AI$10,$L$32:$U$32)+2,$L39,$M39,$N39,$O39,$P39,$Q39,$R39,$S39)) -> 45943 | AJ7: -----
A8: 258 | B8: БИВ | C8: 45913 | D8: 45920 | E8: 45934 | F8: 45941 | H8: Ерохина | L8: 45906 | M8: 45913 | N8: 45920 | O8: 45927 | P8: 45934 | Q8: 45935 | R8: 45941 | S8: 45942 | T8: 45948 | U8: 45949 | V8: Ерохина | X8: =CHOOSE(MATCH(X$10,$L$22:$U$22),$L30,$M30,$N30,$O30,$P30,$Q30,$R30,$S30) -> 45918 | Y8: =CHOOSE(MATCH(Y$10,$L$22:$U$22),$L30,$M30,$N30,$O30,$P30,$Q30,$R30,$S30) -> 45932 | Z8: =IF(OR(CHOOSE(MATCH(Z$10,$L$22:$U$22)+1,$L30,$M30,$N30,$O30,$P30,$Q30,$R30,$S30)>($J$14),CHOOSE(MATCH(Z$10,$L$22:$U$22)+1,$L30,$M30,$N30,$O30,$P30,$Q30,$R30,$S30)=0),"-----",CHOOSE(MATCH(Z$10,$L$22:$U$22)+1,$L30,$M30,$N30,$O30,$P30,$Q30,$R30,$S30)) -> 45925 | AA8: ----- | AB8: =IF(OR(CHOOSE(MATCH(AB$10,$L$22:$U$22)+2,$L30,$M30,$N30,$O30,$P30,$Q30,$R30,$S30)>($J$14),CHOOSE(MATCH(AB$10,$L$22:$U$22)+2,$L30,$M30,$N30,$O30,$P30,$Q30,$R30,$S30)=0),"-----",CHOOSE(MATCH(AB$10,$L$22:$U$22)+2,$L30,$M30,$N30,$O30,$P30,$Q30,$R30,$S30)) -> 45932 | AC8: ----- | AE8: =CHOOSE(MATCH(AE$10,$L$32:$U$32),$L40,$M40,$N40,$O40,$P40,$Q40,$R40,$S40) -> 45912 | AF8: =CHOOSE(MATCH(AF$10,$L$32:$U$32),$L40,$M40,$N40,$O40,$P40,$Q40,$R40,$S40) -> 45914 | AG8: =IF(OR(CHOOSE(MATCH(AG$10,$L$32:$U$32)+1,$L40,$M40,$N40,$O40,$P40,$Q40,$R40,$S40)>($J$14),CHOOSE(MATCH(AG$10,$L$32:$U$32)+1,$L40,$M40,$N40,$O40,$P40,$Q40,$R40,$S40)=0),"-----",CHOOSE(MATCH(AG$10,$L$32:$U$32)+1,$L40,$M40,$N40,$O40,$P40,$Q40,$R40,$S40)) -> 45913 | AH8: ----- | AI8: =IF(OR(CHOOSE(MATCH(AI$10,$L$32:$U$32)+2,$L40,$M40,$N40,$O40,$P40,$Q40,$R40,$S40)>($J$14),CHOOSE(MATCH(AI$10,$L$32:$U$32)+2,$L40,$M40,$N40,$O40,$P40,$Q40,$R40,$S40)=0),"-----",CHOOSE(MATCH(AI$10,$L$32:$U$32)+2,$L40,$M40,$N40,$O40,$P40,$Q40,$R40,$S40)) -> 45914 | AJ8: -----
A9: 259 | B9: БИВ | C9: 45920 | D9: 45932 | E9: 45934 | F9: 45941 | H9: Ерохина | L9: 45906 | M9: 45913 | N9: 45920 | O9: 45927 | P9: 45934 | Q9: 45935 | R9: 45941 | S9: 45942 | T9: 45948 | U9: 45949 | V9: Ерохина | X9: =CHOOSE(MATCH(X$10,$L$22:$U$22),$L30,$M30,$N30,$O30,$P30,$Q30,$R30,$S30) -> 45918 | Y9: =CHOOSE(MATCH(Y$10,$L$22:$U$22),$L30,$M30,$N30,$O30,$P30,$Q30,$R30,$S30) -> 45932 | Z9: =IF(OR(CHOOSE(MATCH(Z$10,$L$22:$U$22)+1,$L30,$M30,$N30,$O30,$P30,$Q30,$R30,$S30)>($J$14),CHOOSE(MATCH(Z$10,$L$22:$U$22)+1,$L30,$M30,$N30,$O30,$P30,$Q30,$R30,$S30)=0),"-----",CHOOSE(MATCH(Z$10,$L$22:$U$22)+1,$L30,$M30,$N30,$O30,$P30,$Q30,$R30,$S30)) -> 45925 | AA9: ----- | AB9: =IF(OR(CHOOSE(MATCH(AB$10,$L$22:$U$22)+2,$L30,$M30,$N30,$O30,$P30,$Q30,$R30,$S30)>($J$14),CHOOSE(MATCH(AB$10,$L$22:$U$22)+2,$L30,$M30,$N30,$O30,$P30,$Q30,$R30,$S30)=0),"-----",CHOOSE(MATCH(AB$10,$L$22:$U$22)+2,$L30,$M30,$N30,$O30,$P30,$Q30,$R30,$S30)) -> 45932 | AC9: ----- | AE9: =CHOOSE(MATCH(AE$10,$L$32:$U$32),$L41,$M41,$N41,$O41,$P41,$Q41,$R41,$S41) -> 45912 | AF9: =CHOOSE(MATCH(AF$10,$L$32:$U$32),$L41,$M41,$N41,$O41,$P41,$Q41,$R41,$S41) -> 45914 | AG9: =IF(OR(CHOOSE(MATCH(AG$10,$L$32:$U$32)+1,$L41,$M41,$N41,$O41,$P41,$Q41,$R41,$S41)>($J$14),CHOOSE(MATCH(AG$10,$L$32:$U$32)+1,$L41,$M41,$N41,$O41,$P41,$Q41,$R41,$S41)=0),"-----",CHOOSE(MATCH(AG$10,$L$32:$U$32)+1,$L41,$M41,$N41,$O41,$P41,$Q41,$R41,$S41)) -> 45913 | AH9: ----- | AI9: =IF(OR(CHOOSE(MATCH(AI$10,$L$32:$U$32)+2,$L41,$M41,$N41,$O41,$P41,$Q41,$R41,$S41)>($J$14),CHOOSE(MATCH(AI$10,$L$32:$U$32)+2,$L41,$M41,$N41,$O41,$P41,$Q41,$R41,$S41)=0),"-----",CHOOSE(MATCH(AI$10,$L$32:$U$32)+2,$L41,$M41,$N41,$O41,$P41,$Q41,$R41,$S41)) -> 45914 | AJ9: -----
X10: 1 | Y10: 2 | Z10: 1 | AA10: 2 | AB10: 1 | AC10: 2 | AE10: 1 | AF10: 2 | AG10: 1 | AH10: 2 | AI10: 1 | AJ10: 2
C11: Семинары | L11: Лекции | X11: Лабораторные | Z11: 1 | AE11: Лабораторные | AG11: 2
X12: 1 | Z12: 0.6 | AB12: 0.4 | AE12: 1 | AG12: 0.6 | AI12: 0.4
C14: Дата окончания модуля | J14: 45956 | R14: 1 | T14: Алгоритмизация и программирование | Z14: 2025/2026
C16: лаб | D16: сем | E16: лекц | F16: к.р. | H16: К.С.
B17: Нак | C17: 7 | D17: 1 | E17: 2 | F17: 0 | H17: =SUM(C17:F17) -> 10
B18: Итог | H18: =SUM(C18:D18) -> 0
B20: 1 | C20: 1 | D20: 1 подгруппа
B21: 2 | C21: 0.6 | L21: дедлайн на неделе 1 лаба и 2 лаба
B22: 3 | C22: 0.4 | M22: 1 | O22: 2
J23: 1 подгруппа | K23: 251 | L23: 45925 | M23: 45932 | N23: 45939 | O23: 45946 | Q23: 1
B24: 1 | C24: 1 | D24: 2 подгруппа | K24: 252 | L24: 45919 | M24: 45926 | N24: 45933 | O24: 45940 | Q24: 3
B25: 2 | C25: 0.6 | K25: 253 | L25: 45924 | M25: 45931 | N25: 45938 | O25: 45945 | Q25: 5
B26: 3 | C26: 0.4 | K26: 254 | L26: 45924 | M26: 45931 | N26: 45938 | O26: 45945 | Q26: 7
K27: 255 | L27: 45926 | M27: 45933 | N27: 45940 | O27: 45945 | Q27: 9
K28: 256 | L28: 45925 | M28: 45932 | N28: 45939 | O28: 45946 | Q28: 11
K29: 257 | L29: 45924 | M29: 45931 | N29: 45938 | O29: 45952 | Q29: 13
K30: 258 | L30: 45911 | M30: 45918 | N30: 45925 | O30: 45932 | Q30: 15
K31: 259 | L31: 45911 | M31: 45911 | N31: 45925 | O31: 45925 | Q31: 17
M32: 1 | O32: 2
J33: 2 подгруппа | K33: 251 | L33: 45925 | M33: 45932 | N33: 45939 | O33: 45946 | Q33: 2
K34: 252 | L34: 45919 | M34: 45926 | N34: 45933 | O34: 45940 | Q34: 4
K35: 253 | L35: 45924 | M35: 45931 | N35: 45938 | O35: 45945 | Q35: 6
K36: 254 | L36: 45925 | M36: 45932 | N36: 45939 | O36: 45946 | Q36: 8
K37: 255 | L37: 45925 | M37: 45932 | N37: 45939 | O37: 45946 | Q37: 10
K38: 256 | L38: 45922 | M38: 45929 | N38: 45936 | O38: 45943 | Q38: 12
K39: 257 | L39: 45922 | M39: 45929 | N39: 45936 | O39: 45943 | Q39: 14
K40: 258 | L40: 45911 | M40: 45912 | N40: 45913 | O40: 45914 | Q40: 16
K41: 259 | L41: 45911 | M41: 45912 | N41: 45913 | O41: 45914 | Q41: 18

Sheet списки групп
A2: № п\п | B2: № вар | C2: подгруппа | D2: Группа 251 | E2: Староста: | H2: № п\п | I2: № вар | J2: подгруппа | K2: 252 | L2: Староста: | O2: № п\п | P2: № вар | Q2: подгруппа | R2: 253 | S2: Староста: | V2: № п\п | W2: № вар | X2: подгруппа | Y2: 254 | Z2: Староста: | AC2: № п\п | AD2: № вар | AE2: подгруппа | AF2: 255 | AG2: Староста: | AJ2: № п\п | AK2: № вар | AL2: подгруппа | AM2: 256 | AN2: Староста: | AR2: № п\п | AS2: № вар | AT2: подгруппа | AU2: 257 | AV2: Староста: | AY2: № п\п | AZ2: № вар | BA2: подгруппа | BB2: 258 | BC2: Староста: | BF2: № п\п | BG2: № вар | BH2: подгруппа | BI2: 259 | BJ2: Староста:
E3: Зам. Старосты: | L3: Зам. Старосты: | S3: Зам. Старосты: | Z3: Зам. Старосты: | AG3: Зам. Старосты: | AN3: Зам. Старосты: | AV3: Зам. Старосты: | BC3: Зам. Старосты: | BJ3: Зам. Старосты:
A5: 1 | B5: 131 | C5: 1 | D5: Амеличев | E5: Иван | F5: Владимирович | H5: 1 | I5: 171 | J5: 1 | K5: Баранова | L5: Мария | M5: Максимовна | O5: 1 | P5: 211 | Q5: 1 | R5: Александров | S5: Арсений | T5: Андреевич | V5: 1 | W5: 251 | X5: 1 | Y5: Абертасова | Z5: Екатерина | AA5: Александровна | AC5: 1 | AD5: 291 | AE5: 1 | AF5: Абашилов | AG5: Магомед | AH5: Тагирович | AJ5: 1 | AK5: 331 | AL5: 1 | AM5: Александров | AN5: Александр | AO5: Александрович | AR5: 1 | AS5: 371 | AT5: 1 | AU5: Абданбаева | AV5: Айдана | AW5: Женишбековна
A6: 2 | B6: 132 | C6: 1 | D6: Бондарь | E6: Алёна | F6: Витальевна | H6: 2 | I6: 172 | J6: 1 | K6: Васина | L6: Наталья | M6: Васильевна | O6: 2 | P6: 212 | Q6: 1 | R6: Белых | S6: Илья | V6: 2 | W6: 252 | X6: 1 | Y6: Андреев | Z6: Глеб | AA6: Андреевич | AC6: 2 | AD6: 292 | AE6: 1 | AF6: Абрамова | AG6: Мария | AH6: Константиновна | AJ6: 2 | AK6: 332 | AL6: 1 | AM6: Батура | AN6: Иван | AO6: Алексеевич | AR6: 2 | AS6: 372 | AT6: 1 | AU6: Абрамов | AV6: Андрей | AW6: Игоревич
A7: 3 | B7: 133 | C7: 1 | D7: Брагута | E7: Иван | F7: Викторович | H7: 3 | I7: 173 | J7: 1 | K7: Воробьев | L7: Леонид | M7: Андреевич | O7: 3 | P7: 213 | Q7: 1 | R7: Беляков | S7: Тимофей | T7: Викторович | V7: 3 | W7: 253 | X7: 1 | Y7: Андреева | Z7: Мария | AA7: Александровна | AC7: 3 | AD7: 293 | AE7: 1 | AF7: Агамалян | AG7: Саркис | AH7: Владимирович | AJ7: 3 | AK7: 333 | AL7: 1 | AM7: Богославский | AN7: Родион | AO7: Станиславович | AR7: 3 | AS7: 373 | AT7: 1 | AU7: Антропова | AV7: Софья | AW7: Дмитриевна
A8: 4 | B8: 134 | C8: 1 | D8: Воронцова | E8: Алиса | F8: Александровна | H8: 4 | I8: 174 | J8: 1 | K8: Галкин | L8: Михаил | M8: Ярославович | O8: 4 | P8: 214 | Q8: 1 | R8: Боттаева | S8: Элина | T8: Арсеновна | V8: 4 | W8: 254 | X8: 1 | Y8: Астанин | Z8: Александр | AA8: Владимирович | AC8: 4 | AD8: 294 | AE8: 1 | AF8: Анчы | AG8: Владимир | AH8: Вячеславович | AJ8: 4 | AK8: 334 | AL8: 1 | AM8: Бондаренко | AN8: Арсений | AO8: Александрович | AR8: 4 | AS8: 374 | AT8: 1 | AU8: Белякова | AV8: Анастасия | AW8: Артемовна
A9: 5 | B9: 135 | C9: 1 | D9: Горбунов | E9: Демид | F9: Александрович | H9: 5 | I9: 175 | J9: 1 | K9: Демина | L9: Анна | M9: Андреевна | O9: 5 | P9: 215 | Q9: 1 | R9: Васильев | S9: Пётр | T9: Владимирович | V9: 5 | W9: 255 | X9: 1 | Y9: Астудийо | Z9: Даниэль | AA9: Рамилевич | AC9: 5 | AD9: 295 | AE9: 1 | AF9: Аслаханов | AG9: Адлан | AH9: Асламбекович | AJ9: 5 | AK9: 335 | AL9: 1 | AM9: Глинкин | AN9: Вячеслав | AO9: Александрович | AR9: 5 | AS9: 375 | AT9: 1 | AU9: Будаев | AV9: Тимур | AW9: Баторович
A10: 6 | B10: 136 | C10: 1 | D10: Григоращенко | E10: Алексей | F10: Андреевич | H10: 6 | I10: 176 | J10: 1 | K10: Егорычев | L10: Даниил | M10: Ильич | O10: 6 | P10: 216 | Q10: 1 | R10: Вронская | S10: Вероника | T10: Владиславовна | V10: 6 | W10: 256 | X10: 1 | Y10: Гладких | Z10: Максим | AA10: Андреевич | AC10: 6 | AD10: 296 | AE10: 1 | AF10: Бова | AG10: Ульяна | AH10: Алексеевна | AJ10: 6 | AK10: 336 | AL10: 1 | AM10: Горячева | AN10: Алиса | AO10: Дмитриевна | AR10: 6 | AS10: 376 | AT10: 1 | AU10: Воробьев | AV10: Владимир | AW10: Юрьевич
A11: 7 | B11: 137 | C11: 1 | D11: Грицук | E11: Иван | F11: Алексеевич | H11: 7 | I11: 177 | J11: 1 | K11: Еремкин | L11: Константин | M11: Сергеевич | O11: 7 | P11: 217 | Q11: 1 | R11: Деречинский | S11: Степан | T11: Денисович | V11: 7 | W11: 257 | X11: 1 | Y11: Грушихин | Z11: Сергей | AA11: Юрьевич | AC11: 7 | AD11: 297 | AE11: 1 | AF11: Борисов | AG11: Александр | AH11: Павлович | AJ11: 7 | AK11: 337 | AL11: 1 | AM11: Жарова | AN11: Екатерина | AO11: Васильевна | AR11: 7 | AS11: 377 | AT11: 1 | AU11: Гобеев | AV11: Алихан | AW11: Владиславович
A12: 8 | B12: 138 | C12: 1 | D12: Евсеева | E12: Елизавета | F12: Алексеевна | H12: 8 | I12: 178 | J12: 1 | K12: Иванов | L12: Никита | M12: Ильич | O12: 8 | P12: 218 | Q12: 1 | R12: Исланов | S12: Амин | T12: Русланович | V12: 8 | W12: 258 | X12: 1 | Y12: Гурушкин | Z12: Андрей | AA12: Александрович | AC12: 8 | AD12: 298 | AE12: 1 | AF12: Бочарский | AG12: Григорий | AH12: Константинович | AJ12: 8 | AK12: 338 | AL12: 1 | AM12: Калинин | AN12: Кирилл | AO12: Константинович | AR12: 8 | AS12: 378 | AT12: 1 | AU12: Давыдов | AV12: Дмитрий | AW12: Олегович
A13: 9 | B13: 139 | C13: 1 | D13: Захаров | E13: Даниил | F13: Дмитриевич | H13: 9 | I13: 179 | J13: 1 | K13: Капитанов | L13: Антон | M13: Петрович | O13: 9 | P13: 219 | Q13: 1 | R13: Ишкин | S13: Артём | T13: Александрович | V13: 9 | W13: 259 | X13: 1 | Y13: Кацаров | Z13: Роберт | AA13: Димитров | AC13: 9 | AD13: 299 | AE13: 1 | AF13: Васильев | AG13: Пётр | AH13: Анатольевич | AJ13: 9 | AK13: 339 | AL13: 1 | AM13: Кошелев | AN13: Николай | AO13: Юрьевич | AR13: 9 | AS13: 379 | AT13: 1 | AU13: Деденёв | AV13: Кирилл | AW13: Дмитриевич
A14: 10 | B14: 140 | C14: 1 | D14: Зотов | E14: Савелий | F14: Вячеславович | H14: 10 | I14: 180 | J14: 1 | K14: Капустин | L14: Роман | M14: Сергеевич | O14: 10 | P14: 220 | Q14: 1 | R14: Караулов | S14: Арсений | T14: Максимович | V14: 10 | W14: 260 | X14: 1 | Y14: Клековкин | Z14: Владислав | AA14: Дмитриевич | AC14: 10 | AD14: 300 | AE14: 1 | AF14: Вдовина | AG14: Марина | AH14: Максимовна | AJ14: 10 | AK14: 340 | AL14: 1 | AM14: Кузнецова | AN14: Алёна | AO14: Павловна | AR14: 10 | AS14: 380 | AT14: 1 | AU14: Жуков | AV14: Игорь | AW14: Максимович
A15: 11 | B15: 141 | C15: 1 | D15: Ивочкин | E15: Никита | F15: Олегович | H15: 11 | I15: 181 | J15: 1 | K15: Коноплев | L15: Кирилл | M15: Владимирович | O15: 11 | P15: 221 | Q15: 1 | R15: Картал | S15: Боян | T15: Бранкович | V15: 11 | W15: 261 | X15: 1 | Y15: Кочетков | Z15: Владислав | AA15: Алексеевич | AC15: 11 | AD15: 301 | AE15: 1 | AF15: Власенков | AG15: Максим | AH15: Максимович | AJ15: 11 | AK15: 341 | AL15: 1 | AM15: Магомедэминов | AN15: Никита | AO15: Сергеевич | AR15: 11 | AS15: 381 | AT15: 1 | AU15: Захаров | AV15: Арсений | AW15: Вадимович
A16: 12 | B16: 142 | C16: 1 | D16: Карташев | E16: Матвей | F16: Евгеньевич | H16: 12 | I16: 182 | J16: 1 | K16: Кузнецова | L16: Арина | M16: Михайловна | O16: 12 | P16: 222 | Q16: 1 | R16: Коновалов | S16: Михаил | T16: Васильевич | V16: 12 | W16: 262 | X16: 1 | Y16: Криушин | Z16: Глеб | AA16: Сергеевич | AC16: 12 | AD16: 302 | AE16: 1 | AF16: Воронков | AG16: Илья | AH16: Дмитриевич | AJ16: 12 | AK16: 342 | AL16: 1 | AM16: Моисеев | AN16: Дмитрий | AO16: Юрьевич | AR16: 12 | AS16: 382 | AT16: 1 | AU16: Ибрагимова | AV16: Саида | AW16: Магомедовна
A17: 13 | B17: 143 | C17: 1 | D17: Кленов | E17: Дмитрий | F17: Станиславович | H17: 13 | I17: 183 | J17: 1 | K17: Лубенец | L17: Илья | M17: Александрович | O17: 13 | P17: 223 | Q17: 1 | R17: Косицын | S17: Василий | T17: Иванович | V17: 13 | W17: 263 | X17: 1 | Y17: Ласточкин | Z17: Сергей | AA17: Владимирович | AC17: 13 | AD17: 303 | AE17: 1 | AF17: Гайдадина | AG17: Мария | AH17: Алексеевна | AJ17: 13 | AK17: 343 | AL17: 1 | AM17: Наташкин | AN17: Евгений | AO17: Сергеевич | AR17: 13 | AS17: 383 | AT17: 1 | AU17: Ким | AV17: Ванэсса | AW17: Кирилловна
A18: 14 | B18: 144 | C18: 1 | D18: Комин | E18: Вадим | F18: Николаевич | H18: 14 | I18: 184 | J18: 1 | K18: Макейчук | L18: Владислава | M18: Юрьевна | O18: 14 | P18: 224 | Q18: 1 | R18: Лазарев | S18: Вадим | T18: Дмитриевич | V18: 14 | W18: 264 | X18: 1 | Y18: Левиков | Z18: Степан | AA18: Юрьевич | AC18: 14 | AD18: 304 | AE18: 1 | AF18: Гордеева | AG18: Анастасия | AH18: Андреевна | AJ18: 14 | AK18: 344 | AL18: 1 | AM18: Остроушко | AN18: Михаил | AO18: Витальевич | AR18: 14 | AS18: 384 | AT18: 1 | AU18: Лапшин | AV18: Дмитрий | AW18: Михайлович
... A32: 28 | B32: 158 | C32: 2 | D32: Шумак | E32: Максим | F32: Геннадьевич | H32: 28 | I32: 198 | J32: 2 | K32: Юсупов | L32: Салман | M32: Рамилевич | O32: 28 | P32: 238 | Q32: 2 | R32: Шишкарев | S32: Иван | T32: Павлович | V32: 28 | W32: 278 | X32: 2 | Y32: Чудакова | Z32: Елизавета | AA32: Павловна | AC32: 28 | AD32: 318 | AE32: 2 | AF32: Шапкин | AG32: Семён | AH32: Григорьевич | AJ32: 28 | AK32: 358 | AL32: 2 | AM32: Шепурев | AN32: Степан | AO32: Сергеевич | AR32: 28 | AS32: 398 | AT32: 2 | AU32: Шохин | AV32: Александр | AW32: Сергеевич
A33: 29 | B33: 29 | H33: 29 | I33: 197 | J33: 2 | K33: Розыкулыев | L33: Дияр | M33: Рустамович | O33: 29 | P33: 110 | V33: 29 | W33: 148 | AC33: 29 | AD33: 188 | AJ33: 29 | AK33: 259 | AL33: 1 | AM33: Глинкин | AN33: Вячеслав | AO33: Александрович | AR33: 29 | AS33: 268
A34: 30 | B34: 30 | H34: 30 | I34: 198 | J34: 1 | K34: Гришук | L34: Илья | M34: Александрович | O34: 30 | P34: 111 | V34: 30 | W34: 149 | AC34: 30 | AD34: 189 | AJ34: 30 | AK34: 229 | AR34: 30 | AS34: 269
A35: 31 | B35: 31 | H35: 31 | I35: 82 | O35: 31 | P35: 112 | V35: 31 | W35: 150 | AC35: 31 | AD35: 190 | AJ35: 31 | AK35: 230 | AR35: 31 | AS35: 270
V36: 32 | W36: 151 | AC36: 32 | AD36: 191 | AJ36: 32 | AK36: 231 | AR36: 32 | AS36: 271
V37: 33 | W37: 152 | AC37: 33 | AD37: 192 | AJ37: 33 | AK37: 232 | AR37: 33 | AS37: 272

Sheet 251-БИВ
A1: =CONCATENATE('Даты занятий'!T14," ",'Даты занятий'!R14," модуль ",'Даты занятий'!Z14, ) -> Алгоритмизация и программирование 1 модуль 2025/2026 | H1: =CONCATENATE('Даты занятий'!A1,"-",'Даты занятий'!B1) -> 251-БИВ
A2: № | B2: Вариант | C2: Подгруппа | D2: Фамилия | E2: Имя | F2: =CONCATENATE("лаб ",L4) -> лаб 1 | H2: =CONCATENATE("лаб ",M4) -> лаб 2 | L2: баллы за лаб.раб. | O2: семинары | T2: лекции | AE2: текущ за модуль | AF2: округл за модуль
F3: =CONCATENATE("часть ",IF(F2<>0,1,RIGHT(D3,1)+1)) -> часть 1 | H3: =CONCATENATE("часть ",IF(H2<>0,1,RIGHT(F3,1)+1)) -> часть 1
F4: Дата | G4: Б | H4: Дата | I4: Б | J4: Дата | K4: Б | L4: 1 | M4: =IF(L4=8,1,L4+1) -> 2 | N4: сумма | O4: =IF(LEFT($H$1,3)="251",'Даты занятий'!C$1,IF(LEFT($H$1,3)="252",'Даты занятий'!C$2,IF(LEFT($H$1,3)="253",'Даты занятий'!C$3,IF(LEFT($H$1,3)="254",'Даты занятий'!C$4,IF(LEFT($H$1,3)="255",'Даты занятий'!C$5,IF(LEFT($H$1,3)="256",'Даты занятий'!C$6,IF(LEFT($H$1,3)="257",'Даты занятий'!C$7, IF(LEFT($H$1,3)="258",'Даты занятий'!C$8, IF(LEFT($H$1,3)="259",'Даты занятий'!C$9,"ERR"))))))))) -> 45917 | P4: =IF(LEFT($H$1,3)="251",'Даты занятий'!D$1,IF(LEFT($H$1,3)="252",'Даты занятий'!D$2,IF(LEFT($H$1,3)="253",'Даты занятий'!D$3,IF(LEFT($H$1,3)="254",'Даты занятий'!D$4,IF(LEFT($H$1,3)="255",'Даты занятий'!D$5,IF(LEFT($H$1,3)="256",'Даты занятий'!D$6,IF(LEFT($H$1,3)="257",'Даты занятий'!D$7, IF(LEFT($H$1,3)="258",'Даты занятий'!D$8, IF(LEFT($H$1,3)="259",'Даты занятий'!D$9,"ERR"))))))))) -> 45924 | Q4: =IF(LEFT($H$1,3)="251",'Даты занятий'!E$1,IF(LEFT($H$1,3)="252",'Даты занятий'!E$2,IF(LEFT($H$1,3)="253",'Даты занятий'!E$3,IF(LEFT($H$1,3)="254",'Даты занятий'!E$4,IF(LEFT($H$1,3)="255",'Даты занятий'!E$5,IF(LEFT($H$1,3)="256",'Даты занятий'!E$6,IF(LEFT($H$1,3)="257",'Даты занятий'!E$7, IF(LEFT($H$1,3)="258",'Даты занятий'!E$8, IF(LEFT($H$1,3)="259",'Даты занятий'!E$9,"ERR"))))))))) -> 45931 | R4: =IF(LEFT($H$1,3)="251",'Даты занятий'!F$1,IF(LEFT($H$1,3)="252",'Даты занятий'!F$2,IF(LEFT($H$1,3)="253",'Даты занятий'!F$3,IF(LEFT($H$1,3)="254",'Даты занятий'!F$4,IF(LEFT($H$1,3)="255",'Даты занятий'!F$5,IF(LEFT($H$1,3)="256",'Даты занятий'!F$6,IF(LEFT($H$1,3)="257",'Даты занятий'!F$7, IF(LEFT($H$1,3)="258",'Даты занятий'!F$8, IF(LEFT($H$1,3)="259",'Даты занятий'!F$9,"ERR"))))))))) -> 45938 | S4: сумма | T4: =IF(LEFT($H$1,3)="251",'Даты занятий'!L$1,IF(LEFT($H$1,3)="252",'Даты занятий'!L$2,IF(LEFT($H$1,3)="253",'Даты занятий'!L$3,IF(LEFT($H$1,3)="254",'Даты занятий'!L$4,IF(LEFT($H$1,3)="255",'Даты занятий'!L$5,IF(LEFT($H$1,3)="256",'Даты занятий'!L$6,IF(LEFT($H$1,3)="257",'Даты занятий'!L$7,IF(LEFT($H$1,3)="258",'Даты занятий'!L$8,IF(LEFT($H$1,3)="259",'Даты занятий'!L$9))))))))) -> 45910 | U4: =IF(LEFT($H$1,3)="251",'Даты занятий'!M$1,IF(LEFT($H$1,3)="252",'Даты занятий'!M$2,IF(LEFT($H$1,3)="253",'Даты занятий'!M$3,IF(LEFT($H$1,3)="254",'Даты занятий'!M$4,IF(LEFT($H$1,3)="255",'Даты занятий'!M$5,IF(LEFT($H$1,3)="256",'Даты занятий'!M$6,IF(LEFT($H$1,3)="257",'Даты занятий'!M$7,IF(LEFT($H$1,3)="258",'Даты занятий'!M$8,IF(LEFT($H$1,3)="259",'Даты занятий'!M$9))))))))) -> 45910 | V4: =IF(LEFT($H$1,3)="251",'Даты занятий'!N$1,IF(LEFT($H$1,3)="252",'Даты занятий'!N$2,IF(LEFT($H$1,3)="253",'Даты занятий'!N$3,IF(LEFT($H$1,3)="254",'Даты занятий'!N$4,IF(LEFT($H$1,3)="255",'Даты занятий'!N$5,IF(LEFT($H$1,3)="256",'Даты занятий'!N$6,IF(LEFT($H$1,3)="257",'Даты занятий'!N$7,IF(LEFT($H$1,3)="258",'Даты занятий'!N$8,IF(LEFT($H$1,3)="259",'Даты занятий'!N$9))))))))) -> 45912 | W4: =IF(LEFT($H$1,3)="251",'Даты занятий'!O$1,IF(LEFT($H$1,3)="252",'Даты занятий'!O$2,IF(LEFT($H$1,3)="253",'Даты занятий'!O$3,IF(LEFT($H$1,3)="254",'Даты занятий'!O$4,IF(LEFT($H$1,3)="255",'Даты занятий'!O$5,IF(LEFT($H$1,3)="256",'Даты занятий'!O$6,IF(LEFT($H$1,3)="257",'Даты занятий'!O$7,IF(LEFT($H$1,3)="258",'Даты занятий'!O$8,IF(LEFT($H$1,3)="259",'Даты занятий'!O$9))))))))) -> 45919 | X4: =IF(LEFT($H$1,3)="251",#REF!,IF(LEFT($H$1,3)="252",'Даты занятий'!P$2,IF(LEFT($H$1,3)="253",'Даты занятий'!P$3,IF(LEFT($H$1,3)="254",'Даты занятий'!P$4,IF(LEFT($H$1,3)="255",'Даты занятий'!P$5,IF(LEFT($H$1,3)="256",'Даты занятий'!P$6,IF(LEFT($H$1,3)="257",'Даты занятий'!P$7,IF(LEFT($H$1,3)="258",'Даты занятий'!P$8,IF(LEFT($H$1,3)="259",'Даты занятий'!P$9))))))))) -> #REF! | Y4: =IF(LEFT($H$1,3)="251",'Даты занятий'!P$1,IF(LEFT($H$1,3)="252",'Даты занятий'!Q$2,IF(LEFT($H$1,3)="253",'Даты занятий'!Q$3,IF(LEFT($H$1,3)="254",'Даты занятий'!Q$4,IF(LEFT($H$1,3)="255",'Даты занятий'!Q$5,IF(LEFT($H$1,3)="256",'Даты занятий'!Q$6,IF(LEFT($H$1,3)="257",'Даты занятий'!Q$7,IF(LEFT($H$1,3)="258",'Даты занятий'!Q$8,IF(LEFT($H$1,3)="259",'Даты занятий'!Q$9))))))))) -> 45924 | Z4: =IF(LEFT($H$1,3)="251",'Даты занятий'!Q$1,IF(LEFT($H$1,3)="252",'Даты занятий'!R$2,IF(LEFT($H$1,3)="253",'Даты занятий'!R$3,IF(LEFT($H$1,3)="254",'Даты занятий'!R$4,IF(LEFT($H$1,3)="255",'Даты занятий'!R$5,IF(LEFT($H$1,3)="256",'Даты занятий'!R$6,IF(LEFT($H$1,3)="257",'Даты занятий'!R$7,IF(LEFT($H$1,3)="258",'Даты занятий'!R$8,IF(LEFT($H$1,3)="259",'Даты занятий'!R$9))))))))) -> 45926 | AA4: =IF(LEFT($H$1,3)="251",'Даты занятий'!R$1,IF(LEFT($H$1,3)="252",'Даты занятий'!S$2,IF(LEFT($H$1,3)="253",'Даты занятий'!S$3,IF(LEFT($H$1,3)="254",'Даты занятий'!S$4,IF(LEFT($H$1,3)="255",'Даты занятий'!S$5,IF(LEFT($H$1,3)="256",'Даты занятий'!S$6,IF(LEFT($H$1,3)="257",'Даты занятий'!S$7,IF(LEFT($H$1,3)="258",'Даты занятий'!S$8,IF(LEFT($H$1,3)="259",'Даты занятий'!S$9))))))))) -> 45931 | AB4: =IF(LEFT($H$1,3)="251",'Даты занятий'!S$1,IF(LEFT($H$1,3)="252",'Даты занятий'!T$2,IF(LEFT($H$1,3)="253",'Даты занятий'!T$3,IF(LEFT($H$1,3)="254",'Даты занятий'!T$4,IF(LEFT($H$1,3)="255",'Даты занятий'!T$5,IF(LEFT($H$1,3)="256",'Даты занятий'!T$6,IF(LEFT($H$1,3)="257",'Даты занятий'!T$7,IF(LEFT($H$1,3)="258",'Даты занятий'!T$8,IF(LEFT($H$1,3)="259",'Даты занятий'!T$9))))))))) -> 45938 | AC4: =IF(LEFT($H$1,3)="251",'Даты занятий'!U$1,IF(LEFT($H$1,3)="252",'Даты занятий'!U$2,IF(LEFT($H$1,3)="253",'Даты занятий'!U$3,IF(LEFT($H$1,3)="254",'Даты занятий'!U$4,IF(LEFT($H$1,3)="255",'Даты занятий'!U$5,IF(LEFT($H$1,3)="256",'Даты занятий'!U$6,IF(LEFT($H$1,3)="257",'Даты занятий'!U$7,IF(LEFT($H$1,3)="258",'Даты занятий'!U$8,IF(LEFT($H$1,3)="259",'Даты занятий'!U$9))))))))) -> 45945 | AD4: сумма
A5: =IF(LEFT($H$1,3)="251",'списки групп'!A5,IF(LEFT($H$1,3)="252",'списки групп'!H5,IF(LEFT($H$1,3)="253",'списки групп'!O5,IF(LEFT($H$1,3)="254",'списки групп'!V5,IF(LEFT($H$1,3)="255",'списки групп'!AC5,IF(LEFT($H$1,3)="256",'списки групп'!AJ5,IF(LEFT($H$1,3)="257",'списки групп'!AR5, IF(LEFT($H$1,3)="258",'списки групп'!AY5, IF(LEFT($H$1,3)="259",'списки групп'!BF5,))))))))) -> 1 | B5: =IF(LEFT($H$1,3)="251",'списки групп'!B5,IF(LEFT($H$1,3)="252",'списки групп'!I5,IF(LEFT($H$1,3)="253",'списки групп'!P5,IF(LEFT($H$1,3)="254",'списки групп'!W5,IF(LEFT($H$1,3)="255",'списки групп'!AD5,IF(LEFT($H$1,3)="256",'списки групп'!AK5,IF(LEFT($H$1,3)="257",'списки групп'!AS5, IF(LEFT($H$1,3)="258",'списки групп'!AZ5, IF(LEFT($H$1,3)="259",'списки групп'!BG5,))))))))) -> 131 | C5: =IF(LEFT($H$1,3)="251",'списки групп'!C5,IF(LEFT($H$1,3)="252",'списки групп'!J5,IF(LEFT($H$1,3)="253",'списки групп'!Q5,IF(LEFT($H$1,3)="254",'списки групп'!X5,IF(LEFT($H$1,3)="255",'списки групп'!AE5,IF(LEFT($H$1,3)="256",'списки групп'!AL5,IF(LEFT($H$1,3)="257",'списки групп'!AT5, IF(LEFT($H$1,3)="258",'списки групп'!BA5, IF(LEFT($H$1,3)="259",'списки групп'!BH5,))))))))) -> 1 | D5: =IF(LEFT($H$1,3)="251",'списки групп'!D5,IF(LEFT($H$1,3)="252",'списки групп'!K5,IF(LEFT($H$1,3)="253",'списки групп'!R5,IF(LEFT($H$1,3)="254",'списки групп'!Y5,IF(LEFT($H$1,3)="255",'списки групп'!AF5,IF(LEFT($H$1,3)="256",'списки групп'!AM5,IF(LEFT($H$1,3)="257",'списки групп'!AU5, IF(LEFT($H$1,3)="258",'списки групп'!BB5, IF(LEFT($H$1,3)="259",'списки групп'!BI5,))))))))) -> Амеличев | E5: =IF(LEFT($H$1,3)="251",'списки групп'!E5,IF(LEFT($H$1,3)="252",'списки групп'!L5,IF(LEFT($H$1,3)="253",'списки групп'!S5,IF(LEFT($H$1,3)="254",'списки групп'!Z5,IF(LEFT($H$1,3)="255",'списки групп'!AG5,IF(LEFT($H$1,3)="256",'списки групп'!AN5,IF(LEFT($H$1,3)="257",'списки групп'!AV5, IF(LEFT($H$1,3)="258",'списки групп'!BC5, IF(LEFT($H$1,3)="259",'списки групп'!BJ5,))))))))) -> Иван | L5: =IF(C5=1,IF(AND(F5<>"----",F5),((10-G$33)+IF(G5<=G$33,G5,G$33))*IF(F5=0,0,IF(F5<=G$36,$E$36,IF(F5<=G$37,$E$37,IF(F5<=G$38,$E$38,0))))*F$34*0.1,0),IF(AND(F5<>"----",F5),((10-G$33)+IF(G5<=G$33,G5,G$33))*IF(F5=0,0,IF(F5<=L$36,$J$36,IF(F5<=L$37,$J$37,IF(F5<=L$38,$J$38,0))))*F$34*0.1,0)) -> 0 | M5: =IF(C5=1,IF(AND(H5<>"----",H5),((10-I$33)+IF(I5<=$I$33,I5,I$33))*IF(H5=0,0,IF(H5<=$H$36,$E$36,IF(H5<=$H$37,$E$36,IF(H5<=$H$38,$E$38,0))))*H$34*0.1,0)+IF(AND(J5<>"----",J5),((10-K$33)+IF(K5<=$I$33,K5,K$33))*IF(J5=0,0,IF(J5<=$H$36,$E$36,IF(J5<=$H$37,$E$36,IF(J5<=$H$38,$E$37,0))))*J$34*0.1,0), IF(AND(H5<>"----",H5),((10-I$33)+IF(I5<=$I$33,I5,I$33))*IF(H5=0,0,IF(H5<=$M$36,$J$36,IF(H5<=$M$37,$J$37,IF(H5<=$M$38,$J$38,0))))*H$34*0.1,0)+IF(AND(J5<>"----",J5),((10-K$33)+IF(K5<=$K$33,K5,K$33))*IF(J5=0,0,IF(J5<=$M$36,$J$36,IF(J5<=$M$37,$J$37,IF(J5<=$M$38,$J$38,0))))*J$34*0.1,0)) -> 0 | N5: =CEILING(SUM(L5:M5)*10/SUM($L$33:$M$33),0.1) -> 0 | S5: =CEILING(SUM(P5:R5)*10/SUM($O$33:$R$33),0.1) -> 0 | AD5: =CEILING(SUM(T5:AC5)*10/SUM($T$33:$AC$33),0.1) -> 0 | AE5: =N5*$N$34+S5*$S$34+AD5*$AD$34 -> 0 | AF5: =ROUND(AE5,0) -> 0
A6: =IF(LEFT($H$1,3)="251",'списки групп'!A6,IF(LEFT($H$1,3)="252",'списки групп'!H6,IF(LEFT($H$1,3)="253",'списки групп'!O6,IF(LEFT($H$1,3)="254",'списки групп'!V6,IF(LEFT($H$1,3)="255",'списки групп'!AC6,IF(LEFT($H$1,3)="256",'списки групп'!AJ6,IF(LEFT($H$1,3)="257",'списки групп'!AR6,IF(LEFT($H$1,3)="258",'списки групп'!AY6,IF(LEFT($H$1,3)="259",'списки групп'!BF6,))))))))) -> 2 | B6: =IF(LEFT($H$1,3)="251",'списки групп'!B6,IF(LEFT($H$1,3)="252",'списки групп'!I6,IF(LEFT($H$1,3)="253",'списки групп'!P6,IF(LEFT($H$1,3)="254",'списки групп'!W6,IF(LEFT($H$1,3)="255",'списки групп'!AD6,IF(LEFT($H$1,3)="256",'списки групп'!AK6,IF(LEFT($H$1,3)="257",'списки групп'!AS6,IF(LEFT($H$1,3)="258",'списки групп'!AZ6,IF(LEFT($H$1,3)="259",'списки групп'!BG6,))))))))) -> 132 | C6: =IF(LEFT($H$1,3)="251",'списки групп'!C6,IF(LEFT($H$1,3)="252",'списки групп'!J6,IF(LEFT($H$1,3)="253",'списки групп'!Q6,IF(LEFT($H$1,3)="254",'списки групп'!X6,IF(LEFT($H$1,3)="255",'списки групп'!AE6,IF(LEFT($H$1,3)="256",'списки групп'!AL6,IF(LEFT($H$1,3)="257",'списки групп'!AT6,IF(LEFT($H$1,3)="258",'списки групп'!BA6,IF(LEFT($H$1,3)="259",'списки групп'!BH6,))))))))) -> 1 | D6: =IF(LEFT($H$1,3)="251",'списки групп'!D6,IF(LEFT($H$1,3)="252",'списки групп'!K6,IF(LEFT($H$1,3)="253",'списки групп'!R6,IF(LEFT($H$1,3)="254",'списки групп'!Y6,IF(LEFT($H$1,3)="255",'списки групп'!AF6,IF(LEFT($H$1,3)="256",'списки групп'!AM6,IF(LEFT($H$1,3)="257",'списки групп'!AU6,IF(LEFT($H$1,3)="258",'списки групп'!BB6,IF(LEFT($H$1,3)="259",'списки групп'!BI6,))))))))) -> Бондарь | E6: =IF(LEFT($H$1,3)="251",'списки групп'!E6,IF(LEFT($H$1,3)="252",'списки групп'!L6,IF(LEFT($H$1,3)="253",'списки групп'!S6,IF(LEFT($H$1,3)="254",'списки групп'!Z6,IF(LEFT($H$1,3)="255",'списки групп'!AG6,IF(LEFT($H$1,3)="256",'списки групп'!AN6,IF(LEFT($H$1,3)="257",'списки групп'!AV6,IF(LEFT($H$1,3)="258",'списки групп'!BC6,IF(LEFT($H$1,3)="259",'списки групп'!BJ6,))))))))) -> Алёна | L6: =IF(C6=1,IF(AND(F6<>"----",F6),((10-G$33)+IF(G6<=G$33,G6,G$33))*IF(F6=0,0,IF(F6<=G$36,$E$36,IF(F6<=G$37,$E$37,IF(F6<=G$38,$E$38,0))))*F$34*0.1,0),IF(AND(F6<>"----",F6),((10-G$33)+IF(G6<=G$33,G6,G$33))*IF(F6=0,0,IF(F6<=L$36,$J$36,IF(F6<=L$37,$J$37,IF(F6<=L$38,$J$38,0))))*F$34*0.1,0)) -> 0 | M6: =IF(C6=1,IF(AND(H6<>"----",H6),((10-I$33)+IF(I6<=$I$33,I6,I$33))*IF(H6=0,0,IF(H6<=$H$36,$E$36,IF(H6<=$H$37,$E$36,IF(H6<=$H$38,$E$38,0))))*H$34*0.1,0)+IF(AND(J6<>"----",J6),((10-K$33)+IF(K6<=$I$33,K6,K$33))*IF(J6=0,0,IF(J6<=$H$36,$E$36,IF(J6<=$H$37,$E$36,IF(J6<=$H$38,$E$37,0))))*J$34*0.1,0), IF(AND(H6<>"----",H6),((10-I$33)+IF(I6<=$I$33,I6,I$33))*IF(H6=0,0,IF(H6<=$M$36,$J$36,IF(H6<=$M$37,$J$37,IF(H6<=$M$38,$J$38,0))))*H$34*0.1,0)+IF(AND(J6<>"----",J6),((10-K$33)+IF(K6<=$K$33,K6,K$33))*IF(J6=0,0,IF(J6<=$M$36,$J$36,IF(J6<=$M$37,$J$37,IF(J6<=$M$38,$J$38,0))))*J$34*0.1,0)) -> 0 | N6: =CEILING(SUM(L6:M6)*10/SUM($L$33:$M$33),0.1) -> 0 | S6: =CEILING(SUM(P6:R6)*10/SUM($O$33:$R$33),0.1) -> 0 | AD6: =CEILING(SUM(T6:AC6)*10/SUM($T$33:$AC$33),0.1) -> 0 | AE6: =N6*$N$34+S6*$S$34+AD6*$AD$34 -> 0 | AF6: =ROUND(AE6,0) -> 0
A7: =IF(LEFT($H$1,3)="251",'списки групп'!A7,IF(LEFT($H$1,3)="252",'списки групп'!H7,IF(LEFT($H$1,3)="253",'списки групп'!O7,IF(LEFT($H$1,3)="254",'списки групп'!V7,IF(LEFT($H$1,3)="255",'списки групп'!AC7,IF(LEFT($H$1,3)="256",'списки групп'!AJ7,IF(LEFT($H$1,3)="257",'списки групп'!AR7,IF(LEFT($H$1,3)="258",'списки групп'!AY7,IF(LEFT($H$1,3)="259",'списки групп'!BF7,))))))))) -> 3 | B7: =IF(LEFT($H$1,3)="251",'списки групп'!B7,IF(LEFT($H$1,3)="252",'списки групп'!I7,IF(LEFT($H$1,3)="253",'списки групп'!P7,IF(LEFT($H$1,3)="254",'списки групп'!W7,IF(LEFT($H$1,3)="255",'списки групп'!AD7,IF(LEFT($H$1,3)="256",'списки групп'!AK7,IF(LEFT($H$1,3)="257",'списки групп'!AS7,IF(LEFT($H$1,3)="258",'списки групп'!AZ7,IF(LEFT($H$1,3)="259",'списки групп'!BG7,))))))))) -> 133 | C7: =IF(LEFT($H$1,3)="251",'списки групп'!C7,IF(LEFT($H$1,3)="252",'списки групп'!J7,IF(LEFT($H$1,3)="253",'списки групп'!Q7,IF(LEFT($H$1,3)="254",'списки групп'!X7,IF(LEFT($H$1,3)="255",'списки групп'!AE7,IF(LEFT($H$1,3)="256",'списки групп'!AL7,IF(LEFT($H$1,3)="257",'списки групп'!AT7,IF(LEFT($H$1,3)="258",'списки групп'!BA7,IF(LEFT($H$1,3)="259",'списки групп'!BH7,))))))))) -> 1 | D7: =IF(LEFT($H$1,3)="251",'списки групп'!D7,IF(LEFT($H$1,3)="252",'списки групп'!K7,IF(LEFT($H$1,3)="253",'списки групп'!R7,IF(LEFT($H$1,3)="254",'списки групп'!Y7,IF(LEFT($H$1,3)="255",'списки групп'!AF7,IF(LEFT($H$1,3)="256",'списки групп'!AM7,IF(LEFT($H$1,3)="257",'списки групп'!AU7,IF(LEFT($H$1,3)="258",'списки групп'!BB7,IF(LEFT($H$1,3)="259",'списки групп'!BI7,))))))))) -> Брагута | E7: =IF(LEFT($H$1,3)="251",'списки групп'!E7,IF(LEFT($H$1,3)="252",'списки групп'!L7,IF(LEFT($H$1,3)="253",'списки групп'!S7,IF(LEFT($H$1,3)="254",'списки групп'!Z7,IF(LEFT($H$1,3)="255",'списки групп'!AG7,IF(LEFT($H$1,3)="256",'списки групп'!AN7,IF(LEFT($H$1,3)="257",'списки групп'!AV7,IF(LEFT($H$1,3)="258",'списки групп'!BC7,IF(LEFT($H$1,3)="259",'списки групп'!BJ7,))))))))) -> Иван | L7: =IF(C7=1,IF(AND(F7<>"----",F7),((10-G$33)+IF(G7<=G$33,G7,G$33))*IF(F7=0,0,IF(F7<=G$36,$E$36,IF(F7<=G$37,$E$37,IF(F7<=G$38,$E$38,0))))*F$34*0.1,0),IF(AND(F7<>"----",F7),((10-G$33)+IF(G7<=G$33,G7,G$33))*IF(F7=0,0,IF(F7<=L$36,$J$36,IF(F7<=L$37,$J$37,IF(F7<=L$38,$J$38,0))))*F$34*0.1,0)) -> 0 | M7: =IF(C7=1,IF(AND(H7<>"----",H7),((10-I$33)+IF(I7<=$I$33,I7,I$33))*IF(H7=0,0,IF(H7<=$H$36,$E$36,IF(H7<=$H$37,$E$36,IF(H7<=$H$38,$E$38,0))))*H$34*0.1,0)+IF(AND(J7<>"----",J7),((10-K$33)+IF(K7<=$I$33,K7,K$33))*IF(J7=0,0,IF(J7<=$H$36,$E$36,IF(J7<=$H$37,$E$36,IF(J7<=$H$38,$E$37,0))))*J$34*0.1,0), IF(AND(H7<>"----",H7),((10-I$33)+IF(I7<=$I$33,I7,I$33))*IF(H7=0,0,IF(H7<=$M$36,$J$36,IF(H7<=$M$37,$J$37,IF(H7<=$M$38,$J$38,0))))*H$34*0.1,0)+IF(AND(J7<>"----",J7),((10-K$33)+IF(K7<=$K$33,K7,K$33))*IF(J7=0,0,IF(J7<=$M$36,$J$36,IF(J7<=$M$37,$J$37,IF(J7<=$M$38,$J$38,0))))*J$34*0.1,0)) -> 0 | N7: =CEILING(SUM(L7:M7)*10/SUM($L$33:$M$33),0.1) -> 0 | S7: =CEILING(SUM(P7:R7)*10/SUM($O$33:$R$33),0.1) -> 0 | AD7: =CEILING(SUM(T7:AC7)*10/SUM($T$33:$AC$33),0.1) -> 0 | AE7: =N7*$N$34+S7*$S$34+AD7*$AD$34 -> 0 | AF7: =ROUND(AE7,0) -> 0
A8: =IF(LEFT($H$1,3)="251",'списки групп'!A8,IF(LEFT($H$1,3)="252",'списки групп'!H8,IF(LEFT($H$1,3)="253",'списки групп'!O8,IF(LEFT($H$1,3)="254",'списки групп'!V8,IF(LEFT($H$1,3)="255",'списки групп'!AC8,IF(LEFT($H$1,3)="256",'списки групп'!AJ8,IF(LEFT($H$1,3)="257",'списки групп'!AR8,IF(LEFT($H$1,3)="258",'списки групп'!AY8,IF(LEFT($H$1,3)="259",'списки групп'!BF8,))))))))) -> 4 | B8: =IF(LEFT($H$1,3)="251",'списки групп'!B8,IF(LEFT($H$1,3)="252",'списки групп'!I8,IF(LEFT($H$1,3)="253",'списки групп'!P8,IF(LEFT($H$1,3)="254",'списки групп'!W8,IF(LEFT($H$1,3)="255",'списки групп'!AD8,IF(LEFT($H$1,3)="256",'списки групп'!AK8,IF(LEFT($H$1,3)="257",'списки групп'!AS8,IF(LEFT($H$1,3)="258",'списки групп'!AZ8,IF(LEFT($H$1,3)="259",'списки групп'!BG8,))))))))) -> 134 | C8: =IF(LEFT($H$1,3)="251",'списки групп'!C8,IF(LEFT($H$1,3)="252",'списки групп'!J8,IF(LEFT($H$1,3)="253",'списки групп'!Q8,IF(LEFT($H$1,3)="254",'списки групп'!X8,IF(LEFT($H$1,3)="255",'списки групп'!AE8,IF(LEFT($H$1,3)="256",'списки групп'!AL8,IF(LEFT($H$1,3)="257",'списки групп'!AT8,IF(LEFT($H$1,3)="258",'списки групп'!BA8,IF(LEFT($H$1,3)="259",'списки групп'!BH8,))))))))) -> 1 | D8: =IF(LEFT($H$1,3)="251",'списки групп'!D8,IF(LEFT($H$1,3)="252",'списки групп'!K8,IF(LEFT($H$1,3)="253",'списки групп'!R8,IF(LEFT($H$1,3)="254",'списки групп'!Y8,IF(LEFT($H$1,3)="255",'списки групп'!AF8,IF(LEFT($H$1,3)="256",'списки групп'!AM8,IF(LEFT($H$1,3)="257",'списки групп'!AU8,IF(LEFT($H$1,3)="258",'списки групп'!BB8,IF(LEFT($H$1,3)="259",'списки групп'!BI8,))))))))) -> Воронцова | E8: =IF(LEFT($H$1,3)="251",'списки групп'!E8,IF(LEFT($H$1,3)="252",'списки групп'!L8,IF(LEFT($H$1,3)="253",'списки групп'!S8,IF(LEFT($H$1,3)="254",'списки групп'!Z8,IF(LEFT($H$1,3)="255",'списки групп'!AG8,IF(LEFT($H$1,3)="256",'списки групп'!AN8,IF(LEFT($H$1,3)="257",'списки групп'!AV8,IF(LEFT($H$1,3)="258",'списки групп'!BC8,IF(LEFT($H$1,3)="259",'списки групп'!BJ8,))))))))) -> Алиса | L8: =IF(C8=1,IF(AND(F8<>"----",F8),((10-G$33)+IF(G8<=G$33,G8,G$33))*IF(F8=0,0,IF(F8<=G$36,$E$36,IF(F8<=G$37,$E$37,IF(F8<=G$38,$E$38,0))))*F$34*0.1,0),IF(AND(F8<>"----",F8),((10-G$33)+IF(G8<=G$33,G8,G$33))*IF(F8=0,0,IF(F8<=L$36,$J$36,IF(F8<=L$37,$J$37,IF(F8<=L$38,$J$38,0))))*F$34*0.1,0)) -> 0 | M8: =IF(C8=1,IF(AND(H8<>"----",H8),((10-I$33)+IF(I8<=$I$33,I8,I$33))*IF(H8=0,0,IF(H8<=$H$36,$E$36,IF(H8<=$H$37,$E$36,IF(H8<=$H$38,$E$38,0))))*H$34*0.1,0)+IF(AND(J8<>"----",J8),((10-K$33)+IF(K8<=$I$33,K8,K$33))*IF(J8=0,0,IF(J8<=$H$36,$E$36,IF(J8<=$H$37,$E$36,IF(J8<=$H$38,$E$37,0))))*J$34*0.1,0), IF(AND(H8<>"----",H8),((10-I$33)+IF(I8<=$I$33,I8,I$33))*IF(H8=0,0,IF(H8<=$M$36,$J$36,IF(H8<=$M$37,$J$37,IF(H8<=$M$38,$J$38,0))))*H$34*0.1,0)+IF(AND(J8<>"----",J8),((10-K$33)+IF(K8<=$K$33,K8,K$33))*IF(J8=0,0,IF(J8<=$M$36,$J$36,IF(J8<=$M$37,$J$37,IF(J8<=$M$38,$J$38,0))))*J$34*0.1,0)) -> 0 | N8: =CEILING(SUM(L8:M8)*10/SUM($L$33:$M$33),0.1) -> 0 | S8: =CEILING(SUM(P8:R8)*10/SUM($O$33:$R$33),0.1) -> 0 | AD8: =CEILING(SUM(T8:AC8)*10/SUM($T$33:$AC$33),0.1) -> 0 | AE8: =N8*$N$34+S8*$S$34+AD8*$AD$34 -> 0 | AF8: =ROUND(AE8,0) -> 0
A9: =IF(LEFT($H$1,3)="251",'списки групп'!A9,IF(LEFT($H$1,3)="252",'списки групп'!H9,IF(LEFT($H$1,3)="253",'списки групп'!O9,IF(LEFT($H$1,3)="254",'списки групп'!V9,IF(LEFT($H$1,3)="255",'списки групп'!AC9,IF(LEFT($H$1,3)="256",'списки групп'!AJ9,IF(LEFT($H$1,3)="257",'списки групп'!AR9,IF(LEFT($H$1,3)="258",'списки групп'!AY9,IF(LEFT($H$1,3)="259",'списки групп'!BF9,))))))))) -> 5 | B9: =IF(LEFT($H$1,3)="251",'списки групп'!B9,IF(LEFT($H$1,3)="252",'списки групп'!I9,IF(LEFT($H$1,3)="253",'списки групп'!P9,IF(LEFT($H$1,3)="254",'списки групп'!W9,IF(LEFT($H$1,3)="255",'списки групп'!AD9,IF(LEFT($H$1,3)="256",'списки групп'!AK9,IF(LEFT($H$1,3)="257",'списки групп'!AS9,IF(LEFT($H$1,3)="258",'списки групп'!AZ9,IF(LEFT($H$1,3)="259",'списки групп'!BG9,))))))))) -> 135 | C9: =IF(LEFT($H$1,3)="251",'списки групп'!C9,IF(LEFT($H$1,3)="252",'списки групп'!J9,IF(LEFT($H$1,3)="253",'списки групп'!Q9,IF(LEFT($H$1,3)="254",'списки групп'!X9,IF(LEFT($H$1,3)="255",'списки групп'!AE9,IF(LEFT($H$1,3)="256",'списки групп'!AL9,IF(LEFT($H$1,3)="257",'списки групп'!AT9,IF(LEFT($H$1,3)="258",'списки групп'!BA9,IF(LEFT($H$1,3)="259",'списки групп'!BH9,))))))))) -> 1 | D9: =IF(LEFT($H$1,3)="251",'списки групп'!D9,IF(LEFT($H$1,3)="252",'списки групп'!K9,IF(LEFT($H$1,3)="253",'списки групп'!R9,IF(LEFT($H$1,3)="254",'списки групп'!Y9,IF(LEFT($H$1,3)="255",'списки групп'!AF9,IF(LEFT($H$1,3)="256",'списки групп'!AM9,IF(LEFT($H$1,3)="257",'списки групп'!AU9,IF(LEFT($H$1,3)="258",'списки групп'!BB9,IF(LEFT($H$1,3)="259",'списки групп'!BI9,))))))))) -> Горбунов | E9: =IF(LEFT($H$1,3)="251",'списки групп'!E9,IF(LEFT($H$1,3)="252",'списки групп'!L9,IF(LEFT($H$1,3)="253",'списки групп'!S9,IF(LEFT($H$1,3)="254",'списки групп'!Z9,IF(LEFT($H$1,3)="255",'списки групп'!AG9,IF(LEFT($H$1,3)="256",'списки групп'!AN9,IF(LEFT($H$1,3)="257",'списки групп'!AV9,IF(LEFT($H$1,3)="258",'списки групп'!BC9,IF(LEFT($H$1,3)="259",'списки групп'!BJ9,))))))))) -> Демид | L9: =IF(C9=1,IF(AND(F9<>"----",F9),((10-G$33)+IF(G9<=G$33,G9,G$33))*IF(F9=0,0,IF(F9<=G$36,$E$36,IF(F9<=G$37,$E$37,IF(F9<=G$38,$E$38,0))))*F$34*0.1,0),IF(AND(F9<>"----",F9),((10-G$33)+IF(G9<=G$33,G9,G$33))*IF(F9=0,0,IF(F9<=L$36,$J$36,IF(F9<=L$37,$J$37,IF(F9<=L$38,$J$38,0))))*F$34*0.1,0)) -> 0 | M9: =IF(C9=1,IF(AND(H9<>"----",H9),((10-I$33)+IF(I9<=$I$33,I9,I$33))*IF(H9=0,0,IF(H9<=$H$36,$E$36,IF(H9<=$H$37,$E$36,IF(H9<=$H$38,$E$38,0))))*H$34*0.1,0)+IF(AND(J9<>"----",J9),((10-K$33)+IF(K9<=$I$33,K9,K$33))*IF(J9=0,0,IF(J9<=$H$36,$E$36,IF(J9<=$H$37,$E$36,IF(J9<=$H$38,$E$37,0))))*J$34*0.1,0), IF(AND(H9<>"----",H9),((10-I$33)+IF(I9<=$I$33,I9,I$33))*IF(H9=0,0,IF(H9<=$M$36,$J$36,IF(H9<=$M$37,$J$37,IF(H9<=$M$38,$J$38,0))))*H$34*0.1,0)+IF(AND(J9<>"----",J9),((10-K$33)+IF(K9<=$K$33,K9,K$33))*IF(J9=0,0,IF(J9<=$M$36,$J$36,IF(J9<=$M$37,$J$37,IF(J9<=$M$38,$J$38,0))))*J$34*0.1,0)) -> 0 | N9: =CEILING(SUM(L9:M9)*10/SUM($L$33:$M$33),0.1) -> 0 | S9: =CEILING(SUM(P9:R9)*10/SUM($O$33:$R$33),0.1) -> 0 | AD9: =CEILING(SUM(T9:AC9)*10/SUM($T$33:$AC$33),0.1) -> 0 | AE9: =N9*$N$34+S9*$S$34+AD9*$AD$34 -> 0 | AF9: =ROUND(AE9,0) -> 0
A10: =IF(LEFT($H$1,3)="251",'списки групп'!A10,IF(LEFT($H$1,3)="252",'списки групп'!H10,IF(LEFT($H$1,3)="253",'списки групп'!O10,IF(LEFT($H$1,3)="254",'списки групп'!V10,IF(LEFT($H$1,3)="255",'списки групп'!AC10,IF(LEFT($H$1,3)="256",'списки групп'!AJ10,IF(LEFT($H$1,3)="257",'списки групп'!AR10, IF(LEFT($H$1,3)="258",'списки групп'!AY10, IF(LEFT($H$1,3)="259",'списки групп'!BF10,))))))))) -> 6 | B10: =IF(LEFT($H$1,3)="251",'списки групп'!B10,IF(LEFT($H$1,3)="252",'списки групп'!I10,IF(LEFT($H$1,3)="253",'списки групп'!P10,IF(LEFT($H$1,3)="254",'списки групп'!W10,IF(LEFT($H$1,3)="255",'списки групп'!AD10,IF(LEFT($H$1,3)="256",'списки групп'!AK10,IF(LEFT($H$1,3)="257",'списки групп'!AS10, IF(LEFT($H$1,3)="258",'списки групп'!AZ10, IF(LEFT($H$1,3)="259",'списки групп'!BG10,))))))))) -> 136 | C10: =IF(LEFT($H$1,3)="251",'списки групп'!C10,IF(LEFT($H$1,3)="252",'списки групп'!J10,IF(LEFT($H$1,3)="253",'списки групп'!Q10,IF(LEFT($H$1,3)="254",'списки групп'!X10,IF(LEFT($H$1,3)="255",'списки групп'!AE10,IF(LEFT($H$1,3)="256",'списки групп'!AL10,IF(LEFT($H$1,3)="257",'списки групп'!AT10, IF(LEFT($H$1,3)="258",'списки групп'!BA10, IF(LEFT($H$1,3)="259",'списки групп'!BH10,))))))))) -> 1 | D10: =IF(LEFT($H$1,3)="251",'списки групп'!D10,IF(LEFT($H$1,3)="252",'списки групп'!K10,IF(LEFT($H$1,3)="253",'списки групп'!R10,IF(LEFT($H$1,3)="254",'списки групп'!Y10,IF(LEFT($H$1,3)="255",'списки групп'!AF10,IF(LEFT($H$1,3)="256",'списки групп'!AM10,IF(LEFT($H$1,3)="257",'списки групп'!AU10, IF(LEFT($H$1,3)="258",'списки групп'!BB10, IF(LEFT($H$1,3)="259",'списки групп'!BI10,))))))))) -> Григоращенко | E10: =IF(LEFT($H$1,3)="251",'списки групп'!E10,IF(LEFT($H$1,3)="252",'списки групп'!L10,IF(LEFT($H$1,3)="253",'списки групп'!S10,IF(LEFT($H$1,3)="254",'списки групп'!Z10,IF(LEFT($H$1,3)="255",'списки групп'!AG10,IF(LEFT($H$1,3)="256",'списки групп'!AN10,IF(LEFT($H$1,3)="257",'списки групп'!AV10, IF(LEFT($H$1,3)="258",'списки групп'!BC10, IF(LEFT($H$1,3)="259",'списки групп'!BJ10,))))))))) -> Алексей | L10: =IF(C10=1,IF(AND(F10<>"----",F10),((10-G$33)+IF(G10<=G$33,G10,G$33))*IF(F10=0,0,IF(F10<=G$36,$E$36,IF(F10<=G$37,$E$37,IF(F10<=G$38,$E$38,0))))*F$34*0.1,0),IF(AND(F10<>"----",F10),((10-G$33)+IF(G10<=G$33,G10,G$33))*IF(F10=0,0,IF(F10<=L$36,$J$36,IF(F10<=L$37,$J$37,IF(F10<=L$38,$J$38,0))))*F$34*0.1,0)) -> 0 | M10: =IF(C10=1,IF(AND(H10<>"----",H10),((10-I$33)+IF(I10<=$I$33,I10,I$33))*IF(H10=0,0,IF(H10<=$H$36,$E$36,IF(H10<=$H$37,$E$36,IF(H10<=$H$38,$E$38,0))))*H$34*0.1,0)+IF(AND(J10<>"----",J10),((10-K$33)+IF(K10<=$I$33,K10,K$33))*IF(J10=0,0,IF(J10<=$H$36,$E$36,IF(J10<=$H$37,$E$36,IF(J10<=$H$38,$E$37,0))))*J$34*0.1,0), IF(AND(H10<>"----",H10),((10-I$33)+IF(I10<=$I$33,I10,I$33))*IF(H10=0,0,IF(H10<=$M$36,$J$36,IF(H10<=$M$37,$J$37,IF(H10<=$M$38,$J$38,0))))*H$34*0.1,0)+IF(AND(J10<>"----",J10),((10-K$33)+IF(K10<=$K$33,K10,K$33))*IF(J10=0,0,IF(J10<=$M$36,$J$36,IF(J10<=$M$37,$J$37,IF(J10<=$M$38,$J$38,0))))*J$34*0.1,0)) -> 0 | N10: =CEILING(SUM(L10:M10)*10/SUM($L$33:$M$33),0.1) -> 0 | S10: =CEILING(SUM(P10:R10)*10/SUM($O$33:$R$33),0.1) -> 0 | AD10: =CEILING(SUM(T10:AC10)*10/SUM($T$33:$AC$33),0.1) -> 0 | AE10: =N10*$N$34+S10*$S$34+AD10*$AD$34 -> 0 | AF10: =ROUND(AE10,0) -> 0
A11: =IF(LEFT($H$1,3)="251",'списки групп'!A11,IF(LEFT($H$1,3)="252",'списки групп'!H11,IF(LEFT($H$1,3)="253",'списки групп'!O11,IF(LEFT($H$1,3)="254",'списки групп'!V11,IF(LEFT($H$1,3)="255",'списки групп'!AC11,IF(LEFT($H$1,3)="256",'списки групп'!AJ11,IF(LEFT($H$1,3)="257",'списки групп'!AR11,IF(LEFT($H$1,3)="258",'списки групп'!AY11,IF(LEFT($H$1,3)="259",'списки групп'!BF11,))))))))) -> 7 | B11: =IF(LEFT($H$1,3)="251",'списки групп'!B11,IF(LEFT($H$1,3)="252",'списки групп'!I11,IF(LEFT($H$1,3)="253",'списки групп'!P11,IF(LEFT($H$1,3)="254",'списки групп'!W11,IF(LEFT($H$1,3)="255",'списки групп'!AD11,IF(LEFT($H$1,3)="256",'списки групп'!AK11,IF(LEFT($H$1,3)="257",'списки групп'!AS11,IF(LEFT($H$1,3)="258",'списки групп'!AZ11,IF(LEFT($H$1,3)="259",'списки групп'!BG11,))))))))) -> 137 | C11: =IF(LEFT($H$1,3)="251",'списки групп'!C11,IF(LEFT($H$1,3)="252",'списки групп'!J11,IF(LEFT($H$1,3)="253",'списки групп'!Q11,IF(LEFT($H$1,3)="254",'списки групп'!X11,IF(LEFT($H$1,3)="255",'списки групп'!AE11,IF(LEFT($H$1,3)="256",'списки групп'!AL11,IF(LEFT($H$1,3)="257",'списки групп'!AT11,IF(LEFT($H$1,3)="258",'списки групп'!BA11,IF(LEFT($H$1,3)="259",'списки групп'!BH11,))))))))) -> 1 | D11: =IF(LEFT($H$1,3)="251",'списки групп'!D11,IF(LEFT($H$1,3)="252",'списки групп'!K11,IF(LEFT($H$1,3)="253",'списки групп'!R11,IF(LEFT($H$1,3)="254",'списки групп'!Y11,IF(LEFT($H$1,3)="255",'списки групп'!AF11,IF(LEFT($H$1,3)="256",'списки групп'!AM11,IF(LEFT($H$1,3)="257",'списки групп'!AU11,IF(LEFT($H$1,3)="258",'списки групп'!BB11,IF(LEFT($H$1,3)="259",'списки групп'!BI11,))))))))) -> Грицук | E11: =IF(LEFT($H$1,3)="251",'списки групп'!E11,IF(LEFT($H$1,3)="252",'списки групп'!L11,IF(LEFT($H$1,3)="253",'списки групп'!S11,IF(LEFT($H$1,3)="254",'списки групп'!Z11,IF(LEFT($H$1,3)="255",'списки групп'!AG11,IF(LEFT($H$1,3)="256",'списки групп'!AN11,IF(LEFT($H$1,3)="257",'списки групп'!AV11,IF(LEFT($H$1,3)="258",'списки групп'!BC11,IF(LEFT($H$1,3)="259",'списки групп'!BJ11,))))))))) -> Иван | L11: =IF(C11=1,IF(AND(F11<>"----",F11),((10-G$33)+IF(G11<=G$33,G11,G$33))*IF(F11=0,0,IF(F11<=G$36,$E$36,IF(F11<=G$37,$E$37,IF(F11<=G$38,$E$38,0))))*F$34*0.1,0),IF(AND(F11<>"----",F11),((10-G$33)+IF(G11<=G$33,G11,G$33))*IF(F11=0,0,IF(F11<=L$36,$J$36,IF(F11<=L$37,$J$37,IF(F11<=L$38,$J$38,0))))*F$34*0.1,0)) -> 0 | M11: =IF(C11=1,IF(AND(H11<>"----",H11),((10-I$33)+IF(I11<=$I$33,I11,I$33))*IF(H11=0,0,IF(H11<=$H$36,$E$36,IF(H11<=$H$37,$E$36,IF(H11<=$H$38,$E$38,0))))*H$34*0.1,0)+IF(AND(J11<>"----",J11),((10-K$33)+IF(K11<=$I$33,K11,K$33))*IF(J11=0,0,IF(J11<=$H$36,$E$36,IF(J11<=$H$37,$E$36,IF(J11<=$H$38,$E$37,0))))*J$34*0.1,0), IF(AND(H11<>"----",H11),((10-I$33)+IF(I11<=$I$33,I11,I$33))*IF(H11=0,0,IF(H11<=$M$36,$J$36,IF(H11<=$M$37,$J$37,IF(H11<=$M$38,$J$38,0))))*H$34*0.1,0)+IF(AND(J11<>"----",J11),((10-K$33)+IF(K11<=$K$33,K11,K$33))*IF(J11=0,0,IF(J11<=$M$36,$J$36,IF(J11<=$M$37,$J$37,IF(J11<=$M$38,$J$38,0))))*J$34*0.1,0)) -> 0 | N11: =CEILING(SUM(L11:M11)*10/SUM($L$33:$M$33),0.1) -> 0 | O11: 2 | S11: =CEILING(SUM(P11:R11)*10/SUM($O$33:$R$33),0.1) -> 0 | AD11: =CEILING(SUM(T11:AC11)*10/SUM($T$33:$AC$33),0.1) -> 0 | AE11: =N11*$N$34+S11*$S$34+AD11*$AD$34 -> 0 | AF11: =ROUND(AE11,0) -> 0
A12: =IF(LEFT($H$1,3)="251",'списки групп'!A12,IF(LEFT($H$1,3)="252",'списки групп'!H12,IF(LEFT($H$1,3)="253",'списки групп'!O12,IF(LEFT($H$1,3)="254",'списки групп'!V12,IF(LEFT($H$1,3)="255",'списки групп'!AC12,IF(LEFT($H$1,3)="256",'списки групп'!AJ12,IF(LEFT($H$1,3)="257",'списки групп'!AR12,IF(LEFT($H$1,3)="258",'списки групп'!AY12,IF(LEFT($H$1,3)="259",'списки групп'!BF12,))))))))) -> 8 | B12: =IF(LEFT($H$1,3)="251",'списки групп'!B12,IF(LEFT($H$1,3)="252",'списки групп'!I12,IF(LEFT($H$1,3)="253",'списки групп'!P12,IF(LEFT($H$1,3)="254",'списки групп'!W12,IF(LEFT($H$1,3)="255",'списки групп'!AD12,IF(LEFT($H$1,3)="256",'списки групп'!AK12,IF(LEFT($H$1,3)="257",'списки групп'!AS12,IF(LEFT($H$1,3)="258",'списки групп'!AZ12,IF(LEFT($H$1,3)="259",'списки групп'!BG12,))))))))) -> 138 | C12: =IF(LEFT($H$1,3)="251",'списки групп'!C12,IF(LEFT($H$1,3)="252",'списки групп'!J12,IF(LEFT($H$1,3)="253",'списки групп'!Q12,IF(LEFT($H$1,3)="254",'списки групп'!X12,IF(LEFT($H$1,3)="255",'списки групп'!AE12,IF(LEFT($H$1,3)="256",'списки групп'!AL12,IF(LEFT($H$1,3)="257",'списки групп'!AT12,IF(LEFT($H$1,3)="258",'списки групп'!BA12,IF(LEFT($H$1,3)="259",'списки групп'!BH12,))))))))) -> 1 | D12: =IF(LEFT($H$1,3)="251",'списки групп'!D12,IF(LEFT($H$1,3)="252",'списки групп'!K12,IF(LEFT($H$1,3)="253",'списки групп'!R12,IF(LEFT($H$1,3)="254",'списки групп'!Y12,IF(LEFT($H$1,3)="255",'списки групп'!AF12,IF(LEFT($H$1,3)="256",'списки групп'!AM12,IF(LEFT($H$1,3)="257",'списки групп'!AU12,IF(LEFT($H$1,3)="258",'списки групп'!BB12,IF(LEFT($H$1,3)="259",'списки групп'!BI12,))))))))) -> Евсеева | E12: =IF(LEFT($H$1,3)="251",'списки групп'!E12,IF(LEFT($H$1,3)="252",'списки групп'!L12,IF(LEFT($H$1,3)="253",'списки групп'!S12,IF(LEFT($H$1,3)="254",'списки групп'!Z12,IF(LEFT($H$1,3)="255",'списки групп'!AG12,IF(LEFT($H$1,3)="256",'списки групп'!AN12,IF(LEFT($H$1,3)="257",'списки групп'!AV12,IF(LEFT($H$1,3)="258",'списки групп'!BC12,IF(LEFT($H$1,3)="259",'списки групп'!BJ12,))))))))) -> Елизавета | L12: =IF(C12=1,IF(AND(F12<>"----",F12),((10-G$33)+IF(G12<=G$33,G12,G$33))*IF(F12=0,0,IF(F12<=G$36,$E$36,IF(F12<=G$37,$E$37,IF(F12<=G$38,$E$38,0))))*F$34*0.1,0),IF(AND(F12<>"----",F12),((10-G$33)+IF(G12<=G$33,G12,G$33))*IF(F12=0,0,IF(F12<=L$36,$J$36,IF(F12<=L$37,$J$37,IF(F12<=L$38,$J$38,0))))*F$34*0.1,0)) -> 0 | M12: =IF(C12=1,IF(AND(H12<>"----",H12),((10-I$33)+IF(I12<=$I$33,I12,I$33))*IF(H12=0,0,IF(H12<=$H$36,$E$36,IF(H12<=$H$37,$E$36,IF(H12<=$H$38,$E$38,0))))*H$34*0.1,0)+IF(AND(J12<>"----",J12),((10-K$33)+IF(K12<=$I$33,K12,K$33))*IF(J12=0,0,IF(J12<=$H$36,$E$36,IF(J12<=$H$37,$E$36,IF(J12<=$H$38,$E$37,0))))*J$34*0.1,0), IF(AND(H12<>"----",H12),((10-I$33)+IF(I12<=$I$33,I12,I$33))*IF(H12=0,0,IF(H12<=$M$36,$J$36,IF(H12<=$M$37,$J$37,IF(H12<=$M$38,$J$38,0))))*H$34*0.1,0)+IF(AND(J12<>"----",J12),((10-K$33)+IF(K12<=$K$33,K12,K$33))*IF(J12=0,0,IF(J12<=$M$36,$J$36,IF(J12<=$M$37,$J$37,IF(J12<=$M$38,$J$38,0))))*J$34*0.1,0)) -> 0 | N12: =CEILING(SUM(L12:M12)*10/SUM($L$33:$M$33),0.1) -> 0 | S12: =CEILING(SUM(P12:R12)*10/SUM($O$33:$R$33),0.1) -> 0 | AD12: =CEILING(SUM(T12:AC12)*10/SUM($T$33:$AC$33),0.1) -> 0 | AE12: =N12*$N$34+S12*$S$34+AD12*$AD$34 -> 0 | AF12: =ROUND(AE12,0) -> 0
